Workbook
Name 存货初始数据: '[1]13 在外库存-2'!$A$1:$W$1
Name 分析: #REF!
Name 核算项目余额表: #REF!
Name 即时库存表: #REF!
Name 科目余额表: #REF!
Name 名称: #REF!
Name 数据啊: #REF!
Name 委托代销明细表: #REF!
Name 委托代销收益分析表: #REF!
Name 现金: #REF!
Name 销售订单汇总表: #REF!
Name 序时簿中心: #REF!
Name 资金: #REF!
Name 分析: #REF!
Name 核算项目余额表: #REF!
Name 即时库存表: #REF!
Name 科目余额表: #REF!
Name 名称: #REF!
Name 数据啊: #REF!
Name 委托代销明细表: #REF!
Name 委托代销收益分析表: #REF!
Name 现金: #REF!
Name 销售订单汇总表: #REF!
Name 序时簿中心: #REF!
Name 资金: #REF!
Name 分析: #REF!
Name 核算项目余额表: #REF!
Name 即时库存表: #REF!
Name 科目余额表: #REF!
Name 名称: #REF!
Name 数据啊: #REF!
Name 委托代销明细表: #REF!
Name 委托代销收益分析表: #REF!
Name 现金: #REF!
Name 销售订单汇总表: #REF!
Name 序时簿中心: #REF!
Name 资金: #REF!
Name 分析: #REF!
Name 核算项目余额表: #REF!
Name 即时库存表: #REF!
Name 科目余额表: #REF!
Name 名称: #REF!
Name 数据啊: #REF!
Name 委托代销明细表: #REF!
Name 委托代销收益分析表: #REF!
Name 现金: #REF!
Name 销售订单汇总表: #REF!
Name 序时簿中心: #REF!
Name 资金: #REF!
Name 分析: #REF!
Name 核算项目余额表: #REF!
Name 即时库存表: #REF!
Name 科目余额表: #REF!
Name 名称: #REF!
Name 数据啊: #REF!
Name 委托代销明细表: #REF!
Name 委托代销收益分析表: #REF!
Name 现金: #REF!
Name 销售订单汇总表: #REF!
Name 序时簿中心: #REF!

Sheet 年度财务收支表
B1: 2026年XX资金收支季度报表
B11: 项目 | C11: 年度合计 | D11: Q1 | E11: Q2 | F11: Q3 | G11: Q4 | I11: 占比
B12: 期初数： | C12: 0 | D12: ='1.建行Q1'!N4 | E12: ='1.建行Q2'!R4
B13: 1、主营收入： | C13: =SUM(D13:H13) | D13: =SUM(D14:D16) | E13: =SUM(E14:E16) | F13: =SUM(F14:F16) | G13: =SUM(G14:G16) | I13: =H13*$H$20
B14: 产品收入 | C14: =汇总表!O9 | D14: =汇总表!O5 | E14: =汇总表!O6 | I14: =H14*$H$20
B15: 服务收入 | C15: =汇总表!O10 | D15: =汇总表!O6 | E15: =汇总表!P6 | I15: =H15*$H$20
B16: 其他收入 | C16: =汇总表!O11 | D16: =汇总表!O7 | E16: =汇总表!Q6 | I16: =H16*$H$20
I17: =H17*$H$20
I18: =H18*$H$20
B19: 2、股东投入： | C19: =汇总表!N9 | D19: =汇总表!N5 | E19: =汇总表!N6 | I19: =H19*$H$20
B20: 本 期 收 入 合 计： | C20: =SUM(D20:H20) | D20: =D19+D13 | E20: =E19+E13 | F20: =F19+F13 | G20: =G19+G13 | I20: =I19+I13
B21: 本 期 支 出 合 计： | C21: =SUM(D21:H21) | D21: =D22+D31+D37+D47+D57+D61+D65+D68+D69+D74 | E21: =E22+E31+E37+E47+E57+E61+E65+E68+E69+E74 | I21: =I22+I31+I37+I47+I57+I61+I65+I68+I69+I74
B22: 1、主营业务支出 | C22: =SUM(D22:H22) | D22: =SUM(D23:D30) | E22: =SUM(E23:E30) | F22: =SUM(F23:F30) | G22: =SUM(G23:G30) | I22: =C22/C21
B23: 商品采购 | C23: =汇总表!V9 | D23: =汇总表!V5 | E23: =汇总表!V6 | I23: =C23/C21
B24: 运费 | C24: =汇总表!V10 | D24: =汇总表!W5 | E24: =汇总表!W6 | I24: =C24/C21
B25: 服务费 | C25: =汇总表!V11 | D25: =汇总表!X5 | E25: =汇总表!X6 | I25: =C25/C21
B26: 返点佣金 | C26: =汇总表!V12 | D26: =汇总表!Y5 | E26: =汇总表!Y6 | I26: =C26/C21
I27: =C27/C21
I28: =C28/C21
I29: =C29/C21
I30: =C30/C21
B31: 2、研发费用 | C31: =SUM(D31:H31) | D31: =SUM(D32:D36) | E31: =SUM(E32:E36) | F31: =SUM(F32:F36) | G31: =SUM(G32:G36) | I31: =C31/$C$21
B32: 人工成本 | C32: =汇总表!Z9 | D32: =汇总表!Z5 | E32: =汇总表!Z6 | I32: =C32/$C$21
B33: 材料设备 | C33: =汇总表!AA9 | D33: =汇总表!AA5 | E33: =汇总表!AA6 | I33: =C33/$C$21
B34: 服务费 | C34: =汇总表!AB9 | D34: =汇总表!AB5 | E34: =汇总表!AB6 | I34: =C34/$C$21
B35: 委外 | C35: =汇总表!AC9 | D35: =汇总表!AC5 | E35: =汇总表!AC6 | I35: =C35/$C$21
I36: =C36/$C$21
B37: 3、销售费用 | C37: =SUM(D37:H37) | D37: =SUM(D38:D46) | E37: =SUM(E38:E46) | F37: =SUM(F38:F46) | G37: =SUM(G38:G46) | I37: =C37/$C$21
B38: 飞机、动车等 | C38: =汇总表!AD9 | D38: =汇总表!AD5 | E38: =汇总表!AD6 | I38: =C38/$C$21
B39: 住宿费 | C39: =汇总表!AE9 | D39: =汇总表!AE5 | E39: =汇总表!AE6 | I39: =C39/$C$21
B40: 车辆费 | C40: =汇总表!AF9 | D40: =汇总表!AF5 | E40: =汇总表!AF6 | I40: =C40/$C$21
B41: 市内交通 | C41: =汇总表!AG9 | D41: =汇总表!AG5 | E41: =汇总表!AG6 | I41: =C41/$C$21
B42: 招待/公关 | C42: =汇总表!AH9 | D42: =汇总表!AH5 | E42: =汇总表!AH6 | I42: =C42/$C$21
B43: 服务费 | C43: =汇总表!AI9 | D43: =汇总表!AI5 | E43: =汇总表!AI6 | I43: =C43/$C$21
B44: 经销返点 | C44: =汇总表!AJ9 | D44: =汇总表!AJ5 | E44: =汇总表!AJ6 | I44: =C44/$C$21
B45: 其他 | C45: =汇总表!AK9 | D45: =汇总表!AK5 | E45: =汇总表!AK6 | I45: =C45/$C$21
I46: =C46/$C$21
B47: 4、管理费用 | C47: =SUM(D47:G47) | D47: =SUM(D48:D56) | E47: =SUM(E48:E56) | F47: =SUM(F48:F56) | G47: =SUM(G48:G56) | I47: =C47/$C$21
B48: 办公费 | C48: =汇总表!AL9 | D48: =汇总表!AL5 | E48: =汇总表!AL6 | I48: =C48/$C$21
B49: 办公租金&物业费&水电费 | C49: =汇总表!AM9 | D49: =汇总表!AM5 | E49: =汇总表!AM6 | I49: =C49/$C$21
...

Sheet 汇总表
A2: 行号 | B2: 交易时间 | C2: 研发费用 | D2: 销售费用 | E2: 管理费用 | F2: 财务费用 | G2: 应缴税金 | H2: 固定资产 | I2: 主营业务支出 | J2: 日常支出和 | K2: 集团往来 | L2: 理财 | M2: 暂支/预付 | N2: 投资款 | O2: 收入 | R2: 余额 | S2: 客户/供应商 | T2: 部门 | U2: 摘要 | V2: 主营业务支出 | Z2: 研发费用 | AD2: 销售费用 | AL2: 管理费用 | AU2: 财务费用 | AX2: 应缴税金 | BC2: 有形资产 | BE2: 营业外支出
O3: 产品收入 | P3: 服务收入 | Q3: 其他收入 | V3: 商品采购 | W3: 运费 | X3: 服务费 | Y3: 返点佣金 | Z3: 人工成本 | AA3: 材料设备 | AB3: 服务费 | AC3: 委外 | AD3: 飞机、动车等 | AE3: 住宿费 | AF3: 车辆费 | AG3: 市内交通 | AH3: 招待/公关 | AI3: 服务费 | AJ3: 经销返点 | AK3: 其他 | AL3: 办公费 | AM3: 办公租金&物业费&水电费 | AN3: 市内交通 | AO3: 招待/公关 | AP3: 飞机、动车等 | AQ3: 人员薪资 | AR3: 社保&公积金 | AS3: 员工福利 | AT3: 其他 | AU3: 手续费 | AV3: 结息 | AW3: 贷款利息 | AX3: 增值税及附加 | AY3: 所得税 | AZ3: 印花税 | BA3: 工资个税 | BB3: 劳务个税 | BC3: 办公设备 | BD3: 办公家具 (包含车等） | BE3: 违约金 | BF3: 罚款
A4: 期初余额 | J4: 0 | R4: 0
A5: 建行 | B5: Q1 | C5: ='1.建行Q1'!C23 | D5: ='1.建行Q1'!D23 | E5: ='1.建行Q1'!E23 | F5: ='1.建行Q1'!F23 | G5: ='1.建行Q1'!G23 | H5: ='1.建行Q1'!H23 | I5: ='1.建行Q1'!I23 | J5: ='1.建行Q1'!J23 | ... BF5: ='1.建行Q1'!BF23
A6: 建行 | B6: Q2 | C6: ='1.建行Q2'!C23 | D6: ='1.建行Q2'!D23 | E6: ='1.建行Q2'!E23 | F6: ='1.建行Q2'!F23 | G6: ='1.建行Q2'!G23 | H6: ='1.建行Q2'!H23 | I6: ='1.建行Q2'!I23 | J6: ='1.建行Q2'!J23 | ... BF6: ='1.建行Q2'!BF23
A7: '1、北京黑金'!A1
A9: 2026年合计 | C9: =SUM(C5:C8) | D9: =SUM(D5:D8) | E9: =SUM(E5:E8) | F9: =SUM(F5:F8) | G9: =SUM(G5:G8) | H9: =SUM(H5:H8) | I9: =SUM(I5:I8) | J9: =SUM(J5:J8) | ... S9: =SUM(S5:S8) | T9: =T4+SUM(N9:S9)-SUM(I9:M9) | U9: =SUM(U5:U8) | V9: =SUM(V5:V8) | W9: =SUM(W5:W8) | X9: =SUM(X5:X8) | Y9: =SUM(Y5:Y8) | Z9: =SUM(Z5:Z8) | AA9: =SUM(AA5:AA8) | AB9: =SUM(AB5:AB8) | AC9: =SUM(AC5:AC8) | AE9: =SUM(AE5:AE8) | AF9: =SUM(AF5:AF8) | AG9: =SUM(AG5:AG8) | AH9: =SUM(AH5:AH8) | AI9: =SUM(AI5:AI8) | AJ9: =SUM(AJ5:AJ8) | AK9: =SUM(AK5:AK8) | AL9: =SUM(AL5:AL8) | ... BF9: =SUM(BF5:BF8)

Sheet 1.建行Q1
A1: ←返回 | F1: 账号名称 | I1: 银行码 | K1: 银行账号
A2: 行号 | B2: 交易时间 | C2: 研发费用 | D2: 销售费用 | E2: 管理费用 | F2: 财务费用 | G2: 应缴税金 | H2: 固定资产 | I2: 主营业务支出 | J2: 日常支出和 | K2: 集团往来 | L2: 理财 | M2: 暂支/预付 | N2: 投资款 | O2: 收入 | R2: 余额 | S2: 客户/供应商 | T2: 部门 | U2: 摘要 | V2: 主营业务支出 | Z2: 研发费用 | AD2: 销售费用 | AL2: 管理费用 | AU2: 财务费用 | AX2: 应缴税金 | BC2: 有形资产 | BE2: 营业外支出
O3: 产品收入 | P3: 服务收入 | Q3: 其他收入 | V3: 商品采购 | W3: 运费 | X3: 服务费 | Y3: 返点佣金 | Z3: 人工成本 | AA3: 材料设备 | AB3: 服务费 | AC3: 委外 | AD3: 飞机、动车等 | AE3: 住宿费 | AF3: 车辆费 | AG3: 市内交通 | AH3: 招待/公关 | AI3: 服务费 | AJ3: 经销返点 | AK3: 其他 | AL3: 办公费 | AM3: 办公租金&物业费&水电费 | AN3: 市内交通 | AO3: 招待/公关 | AP3: 飞机、动车等 | AQ3: 人员薪资 | AR3: 社保&公积金 | AS3: 员工福利 | AT3: 其他 | AU3: 手续费 | AV3: 结息 | AW3: 贷款利息 | AX3: 增值税及附加 | AY3: 所得税 | AZ3: 印花税 | BA3: 工资个税 | BB3: 劳务个税 | BC3: 办公设备 | BD3: 办公家具 (包含车等） | BE3: 违约金 | BF3: 罚款
A4: 期初余额 | J4: 0 | R4: 0
C5: =SUM(Z5:AC5) | D5: =SUM(AD5:AK5) | E5: =SUM(AL5:AT5) | F5: =SUM(AU5:AW5) | G5: =SUM(AX5:BB5) | H5: =SUM(BC5:BD5) | I5: =SUM(V5:Y5) | J5: =SUM(C5:I5) | R5: =R4+SUM(N5:Q5)-SUM(J5:M5)
C6: =SUM(Z6:AC6) | D6: =SUM(AD6:AK6) | E6: =SUM(AL6:AT6) | F6: =SUM(AU6:AW6) | G6: =SUM(AX6:BB6) | H6: =SUM(BC6:BD6) | I6: =SUM(V6:Y6) | J6: =SUM(C6:I6) | R6: =R5+SUM(N6:Q6)-SUM(J6:M6)
C7: =SUM(Z7:AC7) | D7: =SUM(AD7:AK7) | E7: =SUM(AL7:AT7) | F7: =SUM(AU7:AW7) | G7: =SUM(AX7:BB7) | H7: =SUM(BC7:BD7) | I7: =SUM(V7:Y7) | J7: =SUM(C7:I7) | R7: =R6+SUM(N7:Q7)-SUM(J7:M7)
C8: =SUM(Z8:AC8) | D8: =SUM(AD8:AK8) | E8: =SUM(AL8:AT8) | F8: =SUM(AU8:AW8) | G8: =SUM(AX8:BB8) | H8: =SUM(BC8:BD8) | I8: =SUM(V8:Y8) | J8: =SUM(C8:I8) | R8: =R7+SUM(N8:Q8)-SUM(J8:M8)
C9: =SUM(Z9:AC9) | D9: =SUM(AD9:AK9) | E9: =SUM(AL9:AT9) | F9: =SUM(AU9:AW9) | G9: =SUM(AX9:BB9) | H9: =SUM(BC9:BD9) | I9: =SUM(V9:Y9) | J9: =SUM(C9:I9) | R9: =R8+SUM(N9:Q9)-SUM(J9:M9)
C10: =SUM(Z10:AC10) | D10: =SUM(AD10:AK10) | E10: =SUM(AL10:AT10) | F10: =SUM(AU10:AW10) | G10: =SUM(AX10:BB10) | H10: =SUM(BC10:BD10) | I10: =SUM(V10:Y10) | J10: =SUM(C10:I10) | R10: =R9+SUM(N10:Q10)-SUM(J10:M10)
C11: =SUM(Z11:AC11) | D11: =SUM(AD11:AK11) | E11: =SUM(AL11:AT11) | F11: =SUM(AU11:AW11) | G11: =SUM(AX11:BB11) | H11: =SUM(BC11:BD11) | I11: =SUM(V11:Y11) | J11: =SUM(C11:I11) | R11: =R10+SUM(N11:Q11)-SUM(J11:M11)
C12: =SUM(Z12:AC12) | D12: =SUM(AD12:AK12) | E12: =SUM(AL12:AT12) | F12: =SUM(AU12:AW12) | G12: =SUM(AX12:BB12) | H12: =SUM(BC12:BD12) | I12: =SUM(V12:Y12) | J12: =SUM(C12:I12) | R12: =R11+SUM(N12:Q12)-SUM(J12:M12)
C13: =SUM(Z13:AC13) | D13: =SUM(AD13:AK13) | E13: =SUM(AL13:AT13) | F13: =SUM(AU13:AW13) | G13: =SUM(AX13:BB13) | H13: =SUM(BC13:BD13) | I13: =SUM(V13:Y13) | J13: =SUM(C13:I13) | R13: =R12+SUM(N13:Q13)-SUM(J13:M13)
C14: =SUM(Z14:AC14) | D14: =SUM(AD14:AK14) | E14: =SUM(AL14:AT14) | F14: =SUM(AU14:AW14) | G14: =SUM(AX14:BB14) | H14: =SUM(BC14:BD14) | I14: =SUM(V14:Y14) | J14: =SUM(C14:I14) | R14: =R13+SUM(N14:Q14)-SUM(J14:M14)
C15: =SUM(Z15:AC15) | D15: =SUM(AD15:AK15) | E15: =SUM(AL15:AT15) | F15: =SUM(AU15:AW15) | G15: =SUM(AX15:BB15) | H15: =SUM(BC15:BD15) | I15: =SUM(V15:Y15) | J15: =SUM(C15:I15) | R15: =R14+SUM(N15:Q15)-SUM(J15:M15)
C16: =SUM(Z16:AC16) | D16: =SUM(AD16:AK16) | E16: =SUM(AL16:AT16) | F16: =SUM(AU16:AW16) | G16: =SUM(AX16:BB16) | H16: =SUM(BC16:BD16) | I16: =SUM(V16:Y16) | J16: =SUM(C16:I16) | R16: =R15+SUM(N16:Q16)-SUM(J16:M16)
... C21: =SUM(Z21:AC21) | D21: =SUM(AD21:AK21) | E21: =SUM(AL21:AT21) | F21: =SUM(AU21:AW21) | G21: =SUM(AX21:BB21) | H21: =SUM(BC21:BD21) | I21: =SUM(V21:Y21) | J21: =SUM(C21:I21) | R21: =R20+SUM(N21:Q21)-SUM(J21:M21)
C22: =SUM(Z22:AC22) | D22: =SUM(AD22:AK22) | E22: =SUM(AL22:AT22) | F22: =SUM(AU22:AW22) | G22: =SUM(AX22:BB22) | H22: =SUM(BC22:BD22) | I22: =SUM(V22:Y22) | J22: =SUM(C22:I22) | R22: =R21+SUM(O22:Q22)-SUM(J22:N22)
A23: 合计 | D23: =SUM(D5:D22) | E23: =SUM(E5:E22) | F23: =SUM(F5:F22) | G23: =SUM(G5:G22) | H23: =SUM(H5:H22) | I23: =SUM(I5:I22) | J23: =SUM(J5:J22) | K23: =SUM(K5:K22) | ... Q23: =SUM(Q5:Q22) | R23: =SUM(R4+SUM(N23:Q23)-SUM(J23:M23)) | V23: =SUM(V5:V22) | W23: =SUM(W5:W22) | X23: =SUM(X5:X22) | Y23: =SUM(Y5:Y22) | Z23: =SUM(Z5:Z22) | AB23: =SUM(AB5:AB22) | AC23: =SUM(AC5:AC22) | AD23: =SUM(AD5:AD22) | AE23: =SUM(AE5:AE22) | AF23: =SUM(AF5:AF22) | AG23: =SUM(AG5:AG22) | AH23: =SUM(AH5:AH22) | AI23: =SUM(AI5:AI22) | ... BF23: =SUM(BF5:BF22)
A24: 理财产品期初金额 | J24: =SUM(D24:I24)
D25: =SUM(AD25:AK25) | E25: =SUM(AL25:AT25) | F25: =SUM(AU25:AW25) | G25: =SUM(AX25:BB25) | H25: =SUM(BC25:BD25) | I25: =SUM(V25:AC25) | J25: =SUM(D25:I25) | R25: =R24+SUM(O25:Q25)-SUM(J25:N25)
D26: =SUM(AD26:AK26) | E26: =SUM(AL26:AT26) | F26: =SUM(AU26:AW26) | G26: =SUM(AX26:BB26) | H26: =SUM(BC26:BD26) | I26: =SUM(V26:AC26) | J26: =SUM(D26:I26) | R26: =R25+SUM(O26:Q26)-SUM(J26:N26)
R27: =R24+SUM(O27:Q27)-SUM(J27:N27)
A28: 理财产品期末余额 | D28: =SUM(D25:D26) | E28: =SUM(E25:E26) | F28: =SUM(F25:F26) | G28: =SUM(G25:G26) | H28: =SUM(H25:H26) | I28: =SUM(I25:I26) | J28: =SUM(J25:J26) | K28: =SUM(K25:K26) | L28: =SUM(L25:L27) | M28: =SUM(M25:M26) | N28: =SUM(N25:N26) | O28: =SUM(O25:O26) | R28: =R27+SUM(O28:Q28)-SUM(J28:N28) | V28: =SUM(V25:V26) | AA28: =SUM(AA25:AA26) | AC28: =SUM(AC25:AC26)
A29: 合计 | D29: =D28+D23 | E29: =E28+E23 | F29: =F28+F23 | G29: =G28+G23 | H29: =H28+H23 | I29: =I28+I23 | J29: =J28+J23 | K29: =K28+K23 | ... AA29: =AA28+AA23 | AC29: =AC28+AC23 | AD29: =AD28+AD23 | AE29: =AE28+AE23 | AF29: =AF28+AF23 | AG29: =AG28+AG23 | AH29: =AH28+AH23 | AI29: =AI28+AI23 | AJ29: =AJ28+AJ23 | ... BF29: =BF28+BF23

Sheet 1.建行Q2
A1: ←返回 | F1: 账号名称 | I1: 银行码 | K1: 银行账号
A2: 行号 | B2: 交易时间 | C2: 研发费用 | D2: 销售费用 | E2: 管理费用 | F2: 财务费用 | G2: 应缴税金 | H2: 固定资产 | I2: 主营业务支出 | J2: 日常支出和 | K2: 集团往来 | L2: 理财 | M2: 暂支/预付 | N2: 投资款 | O2: 收入 | R2: 余额 | S2: 客户/供应商 | T2: 部门 | U2: 摘要 | V2: 主营业务支出 | Z2: 研发费用 | AD2: 销售费用 | AL2: 管理费用 | AU2: 财务费用 | AX2: 应缴税金 | BC2: 有形资产 | BE2: 营业外支出
O3: 产品收入 | P3: 服务收入 | Q3: 其他收入 | V3: 商品采购 | W3: 运费 | X3: 服务费 | Y3: 返点佣金 | Z3: 人工成本 | AA3: 材料设备 | AB3: 服务费 | AC3: 委外 | AD3: 飞机、动车等 | AE3: 住宿费 | AF3: 车辆费 | AG3: 市内交通 | AH3: 招待/公关 | AI3: 服务费 | AJ3: 经销返点 | AK3: 其他 | AL3: 办公费 | AM3: 办公租金&物业费&水电费 | AN3: 市内交通 | AO3: 招待/公关 | AP3: 飞机、动车等 | AQ3: 人员薪资 | AR3: 社保&公积金 | AS3: 员工福利 | AT3: 其他 | AU3: 手续费 | AV3: 结息 | AW3: 贷款利息 | AX3: 增值税及附加 | AY3: 所得税 | AZ3: 印花税 | BA3: 工资个税 | BB3: 劳务个税 | BC3: 办公设备 | BD3: 办公家具 (包含车等） | BE3: 违约金 | BF3: 罚款
A4: 期初余额 | J4: 0 | R4: ='1.建行Q1'!R23
C5: =SUM(Z5:AC5) | D5: =SUM(AD5:AK5) | E5: =SUM(AL5:AT5) | F5: =SUM(AU5:AW5) | G5: =SUM(AX5:BB5) | H5: =SUM(BC5:BD5) | I5: =SUM(V5:Y5) | J5: =SUM(C5:I5) | R5: =R4+SUM(N5:Q5)-SUM(J5:M5)
C6: =SUM(Z6:AC6) | D6: =SUM(AD6:AK6) | E6: =SUM(AL6:AT6) | F6: =SUM(AU6:AW6) | G6: =SUM(AX6:BB6) | H6: =SUM(BC6:BD6) | I6: =SUM(V6:Y6) | J6: =SUM(C6:I6) | R6: =R5+SUM(N6:Q6)-SUM(J6:M6)
C7: =SUM(Z7:AC7) | D7: =SUM(AD7:AK7) | E7: =SUM(AL7:AT7) | F7: =SUM(AU7:AW7) | G7: =SUM(AX7:BB7) | H7: =SUM(BC7:BD7) | I7: =SUM(V7:Y7) | J7: =SUM(C7:I7) | R7: =R6+SUM(N7:Q7)-SUM(J7:M7)
C8: =SUM(Z8:AC8) | D8: =SUM(AD8:AK8) | E8: =SUM(AL8:AT8) | F8: =SUM(AU8:AW8) | G8: =SUM(AX8:BB8) | H8: =SUM(BC8:BD8) | I8: =SUM(V8:Y8) | J8: =SUM(C8:I8) | R8: =R7+SUM(N8:Q8)-SUM(J8:M8)
C9: =SUM(Z9:AC9) | D9: =SUM(AD9:AK9) | E9: =SUM(AL9:AT9) | F9: =SUM(AU9:AW9) | G9: =SUM(AX9:BB9) | H9: =SUM(BC9:BD9) | I9: =SUM(V9:Y9) | J9: =SUM(C9:I9) | R9: =R8+SUM(N9:Q9)-SUM(J9:M9)
C10: =SUM(Z10:AC10) | D10: =SUM(AD10:AK10) | E10: =SUM(AL10:AT10) | F10: =SUM(AU10:AW10) | G10: =SUM(AX10:BB10) | H10: =SUM(BC10:BD10) | I10: =SUM(V10:Y10) | J10: =SUM(C10:I10) | R10: =R9+SUM(N10:Q10)-SUM(J10:M10)
C11: =SUM(Z11:AC11) | D11: =SUM(AD11:AK11) | E11: =SUM(AL11:AT11) | F11: =SUM(AU11:AW11) | G11: =SUM(AX11:BB11) | H11: =SUM(BC11:BD11) | I11: =SUM(V11:Y11) | J11: =SUM(C11:I11) | R11: =R10+SUM(N11:Q11)-SUM(J11:M11)
C12: =SUM(Z12:AC12) | D12: =SUM(AD12:AK12) | E12: =SUM(AL12:AT12) | F12: =SUM(AU12:AW12) | G12: =SUM(AX12:BB12) | H12: =SUM(BC12:BD12) | I12: =SUM(V12:Y12) | J12: =SUM(C12:I12) | R12: =R11+SUM(N12:Q12)-SUM(J12:M12)
C13: =SUM(Z13:AC13) | D13: =SUM(AD13:AK13) | E13: =SUM(AL13:AT13) | F13: =SUM(AU13:AW13) | G13: =SUM(AX13:BB13) | H13: =SUM(BC13:BD13) | I13: =SUM(V13:Y13) | J13: =SUM(C13:I13) | R13: =R12+SUM(N13:Q13)-SUM(J13:M13)
C14: =SUM(Z14:AC14) | D14: =SUM(AD14:AK14) | E14: =SUM(AL14:AT14) | F14: =SUM(AU14:AW14) | G14: =SUM(AX14:BB14) | H14: =SUM(BC14:BD14) | I14: =SUM(V14:Y14) | J14: =SUM(C14:I14) | R14: =R13+SUM(N14:Q14)-SUM(J14:M14)
C15: =SUM(Z15:AC15) | D15: =SUM(AD15:AK15) | E15: =SUM(AL15:AT15) | F15: =SUM(AU15:AW15) | G15: =SUM(AX15:BB15) | H15: =SUM(BC15:BD15) | I15: =SUM(V15:Y15) | J15: =SUM(C15:I15) | R15: =R14+SUM(N15:Q15)-SUM(J15:M15)
C16: =SUM(Z16:AC16) | D16: =SUM(AD16:AK16) | E16: =SUM(AL16:AT16) | F16: =SUM(AU16:AW16) | G16: =SUM(AX16:BB16) | H16: =SUM(BC16:BD16) | I16: =SUM(V16:Y16) | J16: =SUM(C16:I16) | R16: =R15+SUM(N16:Q16)-SUM(J16:M16)
... C206: =SUM(Z206:AC206) | D206: =SUM(AD206:AK206) | E206: =SUM(AL206:AT206) | F206: =SUM(AU206:AW206) | G206: =SUM(AX206:BB206) | H206: =SUM(BC206:BD206) | I206: =SUM(V206:Y206) | J206: =SUM(C206:I206) | R206: =R205+SUM(N206:Q206)-SUM(J206:M206)
A207: 合计 | C207: =SUM(C5:C206) | D207: =SUM(D5:D206) | E207: =SUM(E5:E206) | F207: =SUM(F5:F206) | G207: =SUM(G5:G206) | H207: =SUM(H5:H206) | I207: =SUM(I5:I206) | J207: =SUM(J5:J206) | ... Q207: =SUM(Q5:Q206) | R207: =SUM(R4+SUM(N207:Q207)-SUM(J207:M207)) | V207: =SUM(V5:V206) | W207: =SUM(W5:W206) | X207: =SUM(X5:X206) | Y207: =SUM(Y5:Y206) | Z207: =SUM(Z5:Z206) | AB207: =SUM(AB5:AB206) | AC207: =SUM(AC5:AC206) | AD207: =SUM(AD5:AD206) | AE207: =SUM(AE5:AE206) | AF207: =SUM(AF5:AF206) | AG207: =SUM(AG5:AG206) | AH207: =SUM(AH5:AH206) | AI207: =SUM(AI5:AI206) | ... BF207: =SUM(BF5:BF206)
A208: 理财产品期初金额
A212: 理财产品期末余额
A213: 合计

Sheet 2、账户
A1: ←返回
A2: 行号 | B2: 交易时间 | C2: 销售费用 | D2: 管理费用 | E2: 财务费用 | F2: 应缴税金 | G2: 固定资产 | H2: 主营业务支出 | I2: 日常支出和 | J2: 集团往来 | K2: 理财 | L2: 提现 | M2: 押金/暂支款 | N2: 收入 | R2: 余额 | S2: 客户/供应商 | T2: 部门 | U2: 摘要 | V2: 主营业务支出 | AB2: 销售费用 | AK2: 管理费用 | AT2: 财务费用 | AV2: 应缴税金 | BA2: 有形资产
N3: 常年咨询服务 | O3: 涉税专项服务 | P3: 财税外包服务 | Q3: 企业培训服务 | V3: 服务费 | W3: 推广费 | X3: 佣金 | Y3: 劳务费 | Z3: 分成 | AA3: 其他 | AB3: 市场宣传 | AC3: 市场辅料 | AD3: 飞机、动车等 | AE3: 住宿费 | AF3: 车辆费 | AG3: 市内交通 | AH3: 招待/公关 | AI3: 服务费 | AJ3: 其他 | AK3: 办公用品&办公费 | AL3: 办公租金&物业费 | AM3: 交通费 | AN3: 招待费 | AO3: 服务费 | AP3: 人员薪资 | AQ3: 社保&公积金 | AR3: 员工福利 | AS3: 其他 | AT3: 手续费 | AU3: 利息 | AV3: 增值税及附加 | AW3: 所得税 | AX3: 印花税 | AY3: 工资个税 | AZ3: 劳务个税 | BA3: 办公设备 | BB3: 办公家具 (包含车等）
A4: XX期初余额 | R4: 0
C5: =SUM(AB5:AJ5) | D5: =SUM(AK5:AS5) | E5: =SUM(AT5:AU5) | F5: =SUM(AV5:AZ5) | G5: =SUM(BA5:BD5) | H5: =SUM(V5:AA5) | I5: =SUM(C5:H5) | R5: =R4+SUM(N5:Q5)-SUM(I5:M5) | BE5: =I5-SUM(AB5:BD5)
C6: =SUM(AB6:AJ6) | D6: =SUM(AK6:AS6) | E6: =SUM(AT6:AU6) | F6: =SUM(AV6:AZ6) | G6: =SUM(BA6:BD6) | H6: =SUM(V6:AA6) | I6: =SUM(C6:H6) | R6: =R5+SUM(N6:Q6)-SUM(I6:M6) | BE6: =I6-SUM(AB6:BD6)
C7: =SUM(AB7:AJ7) | D7: =SUM(AK7:AS7) | E7: =SUM(AT7:AU7) | F7: =SUM(AV7:AZ7) | G7: =SUM(BA7:BD7) | H7: =SUM(V7:AA7) | I7: =SUM(C7:H7) | R7: =R6+SUM(N7:Q7)-SUM(I7:M7) | BE7: =I7-SUM(AB7:BD7)
C8: =SUM(AB8:AJ8) | D8: =SUM(AK8:AS8) | E8: =SUM(AT8:AU8) | F8: =SUM(AV8:AZ8) | G8: =SUM(BA8:BD8) | H8: =SUM(V8:AA8) | I8: =SUM(C8:H8) | R8: =R7+SUM(N8:Q8)-SUM(I8:M8) | BE8: =I8-SUM(AB8:BD8)
C9: =SUM(AB9:AJ9) | D9: =SUM(AK9:AS9) | E9: =SUM(AT9:AU9) | F9: =SUM(AV9:AZ9) | G9: =SUM(BA9:BD9) | H9: =SUM(V9:AA9) | I9: =SUM(C9:H9) | R9: =R8+SUM(N9:Q9)-SUM(I9:M9) | BE9: =I9-SUM(AB9:BD9)
C10: =SUM(AB10:AJ10) | D10: =SUM(AK10:AS10) | E10: =SUM(AT10:AU10) | F10: =SUM(AV10:AZ10) | G10: =SUM(BA10:BD10) | H10: =SUM(V10:AA10) | I10: =SUM(C10:H10) | R10: =R9+SUM(N10:Q10)-SUM(I10:M10) | BE10: =I10-SUM(AB10:BD10)
C11: =SUM(AB11:AJ11) | D11: =SUM(AK11:AS11) | E11: =SUM(AT11:AU11) | F11: =SUM(AV11:AZ11) | G11: =SUM(BA11:BD11) | H11: =SUM(V11:AA11) | I11: =SUM(C11:H11) | R11: =R10+SUM(N11:Q11)-SUM(I11:M11) | BE11: =I11-SUM(AB11:BD11)
C12: =SUM(AB12:AJ12) | D12: =SUM(AK12:AS12) | E12: =SUM(AT12:AU12) | F12: =SUM(AV12:AZ12) | G12: =SUM(BA12:BD12) | H12: =SUM(V12:AA12) | I12: =SUM(C12:H12) | R12: =R11+SUM(N12:Q12)-SUM(I12:M12) | BE12: =I12-SUM(AB12:BD12)
C13: =SUM(AB13:AJ13) | D13: =SUM(AK13:AS13) | E13: =SUM(AT13:AU13) | F13: =SUM(AV13:AZ13) | G13: =SUM(BA13:BD13) | H13: =SUM(V13:AA13) | I13: =SUM(C13:H13) | R13: =R12+SUM(N13:Q13)-SUM(I13:M13) | BE13: =I13-SUM(AB13:BD13)
C14: =SUM(AB14:AJ14) | D14: =SUM(AK14:AS14) | E14: =SUM(AT14:AU14) | F14: =SUM(AV14:AZ14) | G14: =SUM(BA14:BD14) | H14: =SUM(V14:AA14) | I14: =SUM(C14:H14) | R14: =R13+SUM(N14:Q14)-SUM(I14:M14) | BE14: =I14-SUM(AB14:BD14)
C15: =SUM(AB15:AJ15) | D15: =SUM(AK15:AS15) | E15: =SUM(AT15:AU15) | F15: =SUM(AV15:AZ15) | G15: =SUM(BA15:BD15) | H15: =SUM(V15:AA15) | I15: =SUM(C15:H15) | R15: =R14+SUM(N15:Q15)-SUM(I15:M15) | BE15: =I15-SUM(AB15:BD15)
C16: =SUM(AB16:AJ16) | D16: =SUM(AK16:AS16) | E16: =SUM(AT16:AU16) | F16: =SUM(AV16:AZ16) | G16: =SUM(BA16:BD16) | H16: =SUM(V16:AA16) | I16: =SUM(C16:H16) | R16: =R15+SUM(N16:Q16)-SUM(I16:M16) | BE16: =I16-SUM(AB16:BD16)
... C45: =SUM(AB45:AJ45) | D45: =SUM(AK45:AS45) | E45: =SUM(AT45:AU45) | F45: =SUM(AV45:AZ45) | G45: =SUM(BA45:BD45) | H45: =SUM(V45:AA45) | I45: =SUM(C45:H45) | R45: =R44+SUM(N45:Q45)-SUM(I45:M45) | BE45: =I45-SUM(AB45:BD45)
C46: =SUM(AB46:AJ46) | D46: =SUM(AK46:AS46) | E46: =SUM(AT46:AU46) | F46: =SUM(AV46:AZ46) | G46: =SUM(BA46:BD46) | H46: =SUM(V46:AA46) | I46: =SUM(C46:H46) | R46: =R45+SUM(N46:Q46)-SUM(I46:M46)
C47: =SUM(AB47:AJ47) | D47: =SUM(AK47:AS47) | E47: =SUM(AT47:AU47) | F47: =SUM(AV47:AZ47) | G47: =SUM(BA47:BD47) | H47: =SUM(V47:AA47) | I47: =SUM(C47:H47) | R47: =R46+SUM(N47:Q47)-SUM(I47:M47) | BE47: =I47-SUM(AB47:BD47)
C48: =SUM(AB48:AJ48) | D48: =SUM(AK48:AS48) | E48: =SUM(AT48:AU48) | F48: =SUM(AV48:AZ48) | G48: =SUM(BA48:BD48) | H48: =SUM(V48:AA48) | I48: =SUM(C48:H48) | R48: =R47+SUM(N48:Q48)-SUM(I48:M48) | BE48: =I48-SUM(AB48:BD48)
C49: =SUM(AB49:AJ49) | D49: =SUM(AK49:AS49) | E49: =SUM(AT49:AU49) | F49: =SUM(AV49:AZ49) | G49: =SUM(BA49:BD49) | H49: =SUM(V49:AA49) | I49: =SUM(C49:H49) | R49: =R48+SUM(N49:Q49)-SUM(I49:M49) | BE49: =I49-SUM(AB49:BD49)
C50: =SUM(AB50:AJ50) | D50: =SUM(AK50:AS50) | E50: =SUM(AT50:AU50) | F50: =SUM(AV50:AZ50) | G50: =SUM(BA50:BD50) | H50: =SUM(V50:AA50) | I50: =SUM(C50:H50) | R50: =R49+SUM(N50:Q50)-SUM(I50:M50) | BE50: =I50-SUM(AB50:BD50)
C51: =SUM(AB51:AJ51) | D51: =SUM(AK51:AS51) | E51: =SUM(AT51:AU51) | F51: =SUM(AV51:AZ51) | G51: =SUM(BA51:BD51) | H51: =SUM(V51:AA51) | I51: =SUM(C51:H51) | R51: =R50+SUM(N51:Q51)-SUM(I51:M51) | BE51: =I51-SUM(AB51:BD51)
C52: =SUM(AB52:AJ52) | D52: =SUM(AK52:AS52) | E52: =SUM(AT52:AU52) | F52: =SUM(AV52:AZ52) | G52: =SUM(BA52:BD52) | H52: =SUM(V52:AA52) | I52: =SUM(C52:H52) | R52: =R51+SUM(N52:Q52)-SUM(I52:M52) | BE52: =I52-SUM(AB52:BD52)
C53: =SUM(AB53:AJ53) | D53: =SUM(AK53:AS53) | E53: =SUM(AT53:AU53) | F53: =SUM(AV53:AZ53) | G53: =SUM(BA53:BD53) | H53: =SUM(V53:AA53) | I53: =SUM(C53:H53) | R53: =R52+SUM(N53:Q53)-SUM(I53:M53) | BE53: =I53-SUM(AB53:BD53)
C54: =SUM(AB54:AJ54) | D54: =SUM(AK54:AS54) | E54: =SUM(AT54:AU54) | F54: =SUM(AV54:AZ54) | G54: =SUM(BA54:BD54) | H54: =SUM(V54:AA54) | I54: =SUM(C54:H54) | R54: =R53+SUM(N54:Q54)-SUM(I54:M54) | BE54: =I54-SUM(AB54:BD54)
C55: =SUM(AB55:AJ55) | D55: =SUM(AK55:AS55) | E55: =SUM(AT55:AU55) | F55: =SUM(AV55:AZ55) | G55: =SUM(BA55:BD55) | H55: =SUM(V55:AA55) | I55: =SUM(C55:H55) | R55: =R54+SUM(N55:Q55)-SUM(I55:M55) | BE55: =I55-SUM(AB55:BD55)
C56: =SUM(AB56:AJ56) | D56: =SUM(AK56:AS56) | E56: =SUM(AT56:AU56) | F56: =SUM(AV56:AZ56) | G56: =SUM(BA56:BD56) | H56: =SUM(V56:AA56) | I56: =SUM(C56:H56) | R56: =R55+SUM(N56:Q56)-SUM(I56:M56) | BE56: =I56-SUM(AB56:BD56)
C57: =SUM(AB57:AJ57) | D57: =SUM(AK57:AS57) | E57: =SUM(AT57:AU57) | F57: =SUM(AV57:AZ57) | G57: =SUM(BA57:BD57) | H57: =SUM(V57:AA57) | I57: =SUM(C57:H57) | R57: =R56+SUM(N57:Q57)-SUM(I57:M57) | BE57: =I57-SUM(AB57:BD57)
C58: =SUM(AB58:AJ58) | D58: =SUM(AK58:AS58) | E58: =SUM(AT58:AU58) | F58: =SUM(AV58:AZ58) | G58: =SUM(BA58:BD58) | H58: =SUM(V58:AA58) | I58: =SUM(C58:H58) | R58: =R57+SUM(N58:Q58)-SUM(I58:M58) | BE58: =I58-SUM(AB58:BD58)
... C113: =SUM(AB113:AJ113) | D113: =SUM(AK113:AS113) | E113: =SUM(AT113:AU113) | F113: =SUM(AV113:AZ113) | G113: =SUM(BA113:BD113) | H113: =SUM(V113:AA113) | I113: =SUM(C113:H113) | R113: =R112+SUM(N113:Q113)-SUM(I113:M113) | BE113: =I113-SUM(AB113:BD113)
A114: 合计 | C114: =SUM(C5:C113) | D114: =SUM(D5:D113) | E114: =SUM(E5:E113) | F114: =SUM(F5:F113) | G114: =SUM(G5:G113) | H114: =SUM(H5:H113) | I114: =SUM(I5:I113) | J114: =SUM(J5:J113) | ... N114: =SUM(N5:N113) | P114: =SUM(P5:P113) | Q114: =SUM(Q5:Q113) | R114: =R4+N114+P114+Q114-M114-L114-K114-J114-I114 | V114: =SUM(V5:V113) | W114: =SUM(W5:W113) | X114: =SUM(X5:X113) | Y114: =SUM(Y5:Y113) | Z114: =SUM(Z5:Z113) | AA114: =SUM(AA5:AA113) | AB114: =SUM(AB5:AB113) | AC114: =SUM(AC5:AC113) | ... BD114: =SUM(BD5:BD113) | BE114: =I114-SUM(AB114:BD114)
A115: SPD-5465-理财产品期初余额 | I115: =SUM(C115:H115) | R115: =R114+SUM(N115:Q115)-SUM(I115:M115)
C116: =SUM(AB116:AJ116) | D116: =SUM(AK116:AS116) | E116: =SUM(AT116:AU116) | F116: =SUM(AV116:AZ116) | G116: =SUM(BA116:BD116) | H116: =SUM(V116:AA116) | I116: =SUM(C116:H116) | R116: =R115+SUM(N116:Q116)-SUM(I116:M116) | BE116: =I116-SUM(AB116:BD116)
C117: =SUM(AB117:AJ117) | D117: =SUM(AK117:AS117) | E117: =SUM(AT117:AU117) | F117: =SUM(AV117:AZ117) | G117: =SUM(BA117:BD117) | H117: =SUM(V117:AA117) | I117: =SUM(C117:H117) | R117: =R116+SUM(N117:Q117)-SUM(I117:M117) | BE117: =I117-SUM(AB117:BD117)
C118: =SUM(AB118:AJ118) | D118: =SUM(AK118:AS118) | E118: =SUM(AT118:AU118) | F118: =SUM(AV118:AZ118) | G118: =SUM(BA118:BD118) | H118: =SUM(V118:AA118) | I118: =SUM(C118:H118) | R118: =R117+SUM(N118:Q118)-SUM(I118:M118) | BE118: =I118-SUM(AB118:BD118)
R119: =R118+SUM(N119:Q119)-SUM(I119:M119)
C120: =SUM(AB120:AJ120) | D120: =SUM(AK120:AS120) | E120: =SUM(AT120:AU120) | F120: =SUM(AV120:AZ120) | G120: =SUM(BA120:BD120) | H120: =SUM(V120:AA120) | I120: =SUM(C120:H120) | R120: =R119+SUM(N120:Q120)-SUM(I120:M120) | BE120: =I120-SUM(AB120:BD120)
R121: =R120+SUM(N121:Q121)-SUM(I121:M121)
A122: SFD-5465-理财产品小计 | C122: =SUM(C116:C120) | D122: =SUM(D116:D120) | E122: =SUM(E116:E120) | F122: =SUM(F116:F120) | G122: =SUM(G116:G120) | H122: =SUM(H116:H120) | I122: =SUM(I116:I120) | J122: =SUM(J116:J120) | K122: =SUM(K116:K121) | L122: =SUM(L116:L120) | M122: =SUM(M116:M120) | N122: =SUM(N116:N120) | P122: =SUM(P116:P120) | Q122: =SUM(Q116:Q120) | R122: =R121+SUM(N122:Q122)-SUM(I122:M122) | V122: =SUM(V116:V120) | X122: =SUM(X116:X120) | Z122: =SUM(Z116:Z120) | AA122: =SUM(AA116:AA120) | AB122: =SUM(AB116:AB120) | AD122: =SUM(AD116:AD120) | AE122: =SUM(AE116:AE120) | AF122: =SUM(AF116:AF120) | AG122: =SUM(AG116:AG120) | AH122: =SUM(AH116:AH120) | AI122: =SUM(AI116:AI120) | AJ122: =SUM(AJ116:AJ120) | AK122: =SUM(AK116:AK120) | ... BD122: =SUM(BD116:BD120) | BE122: =I122-SUM(AB122:BD122)

Sheet 3、账户
A1: ←返回
A2: 行号 | B2: 交易时间 | C2: 销售费用 | D2: 管理费用 | E2: 财务费用 | F2: 应缴税金 | G2: 固定资产 | H2: 主营业务支出 | I2: 日常支出和 | J2: 集团往来 | K2: 理财 | L2: 提现 | M2: 押金/暂支款 | N2: 收入 | R2: 余额 | S2: 客户/供应商 | T2: 部门 | U2: 摘要 | V2: 主营业务支出 | AB2: 销售费用 | AK2: 管理费用 | AT2: 财务费用 | AV2: 应缴税金 | BA2: 有形资产
N3: 常年咨询服务 | O3: 涉税专项服务 | P3: 财税外包服务 | Q3: 企业培训服务 | V3: 服务费 | W3: 推广费 | X3: 佣金 | Y3: 劳务费 | Z3: 分成 | AA3: 其他 | AB3: 市场宣传 | AC3: 市场辅料 | AD3: 飞机、动车等 | AE3: 住宿费 | AF3: 车辆费 | AG3: 市内交通 | AH3: 招待/公关 | AI3: 服务费 | AJ3: 其他 | AK3: 办公用品&办公费 | AL3: 办公租金&物业费 | AM3: 交通费 | AN3: 招待费 | AO3: 服务费 | AP3: 人员薪资 | AQ3: 社保&公积金 | AR3: 员工福利 | AS3: 其他 | AT3: 手续费 | AU3: 利息 | AV3: 增值税及附加 | AW3: 所得税 | AX3: 印花税 | AY3: 工资个税 | AZ3: 劳务个税 | BA3: 办公设备 | BB3: 办公家具 (包含车等）
A4: XX期初余额 | R4: 0
C5: =SUM(AB5:AJ5) | D5: =SUM(AK5:AS5) | E5: =SUM(AT5:AU5) | F5: =SUM(AV5:AZ5) | G5: =SUM(BA5:BD5) | H5: =SUM(V5:AA5) | I5: =SUM(C5:H5) | R5: =R4+SUM(N5:Q5)-SUM(I5:M5) | BE5: =I5-SUM(AB5:BD5)
C6: =SUM(AB6:AJ6) | D6: =SUM(AK6:AS6) | E6: =SUM(AT6:AU6) | F6: =SUM(AV6:AZ6) | G6: =SUM(BA6:BD6) | H6: =SUM(V6:AA6) | I6: =SUM(C6:H6) | R6: =R5+SUM(N6:Q6)-SUM(I6:M6) | BE6: =I6-SUM(AB6:BD6)
C7: =SUM(AB7:AJ7) | D7: =SUM(AK7:AS7) | E7: =SUM(AT7:AU7) | F7: =SUM(AV7:AZ7) | G7: =SUM(BA7:BD7) | H7: =SUM(V7:AA7) | I7: =SUM(C7:H7) | R7: =R6+SUM(N7:Q7)-SUM(I7:M7) | BE7: =I7-SUM(AB7:BD7)
C8: =SUM(AB8:AJ8) | D8: =SUM(AK8:AS8) | E8: =SUM(AT8:AU8) | F8: =SUM(AV8:AZ8) | G8: =SUM(BA8:BD8) | H8: =SUM(V8:AA8) | I8: =SUM(C8:H8) | R8: =R7+SUM(N8:Q8)-SUM(I8:M8) | BE8: =I8-SUM(AB8:BD8)
C9: =SUM(AB9:AJ9) | D9: =SUM(AK9:AS9) | E9: =SUM(AT9:AU9) | F9: =SUM(AV9:AZ9) | G9: =SUM(BA9:BD9) | H9: =SUM(V9:AA9) | I9: =SUM(C9:H9) | R9: =R8+SUM(N9:Q9)-SUM(I9:M9) | BE9: =I9-SUM(AB9:BD9)
C10: =SUM(AB10:AJ10) | D10: =SUM(AK10:AS10) | E10: =SUM(AT10:AU10) | F10: =SUM(AV10:AZ10) | G10: =SUM(BA10:BD10) | H10: =SUM(V10:AA10) | I10: =SUM(C10:H10) | R10: =R9+SUM(N10:Q10)-SUM(I10:M10) | BE10: =I10-SUM(AB10:BD10)
C11: =SUM(AB11:AJ11) | D11: =SUM(AK11:AS11) | E11: =SUM(AT11:AU11) | F11: =SUM(AV11:AZ11) | G11: =SUM(BA11:BD11) | H11: =SUM(V11:AA11) | I11: =SUM(C11:H11) | R11: =R10+SUM(N11:Q11)-SUM(I11:M11) | BE11: =I11-SUM(AB11:BD11)
C12: =SUM(AB12:AJ12) | D12: =SUM(AK12:AS12) | E12: =SUM(AT12:AU12) | F12: =SUM(AV12:AZ12) | G12: =SUM(BA12:BD12) | H12: =SUM(V12:AA12) | I12: =SUM(C12:H12) | R12: =R11+SUM(N12:Q12)-SUM(I12:M12) | BE12: =I12-SUM(AB12:BD12)
C13: =SUM(AB13:AJ13) | D13: =SUM(AK13:AS13) | E13: =SUM(AT13:AU13) | F13: =SUM(AV13:AZ13) | G13: =SUM(BA13:BD13) | H13: =SUM(V13:AA13) | I13: =SUM(C13:H13) | R13: =R12+SUM(N13:Q13)-SUM(I13:M13) | BE13: =I13-SUM(AB13:BD13)
C14: =SUM(AB14:AJ14) | D14: =SUM(AK14:AS14) | E14: =SUM(AT14:AU14) | F14: =SUM(AV14:AZ14) | G14: =SUM(BA14:BD14) | H14: =SUM(V14:AA14) | I14: =SUM(C14:H14) | R14: =R13+SUM(N14:Q14)-SUM(I14:M14) | BE14: =I14-SUM(AB14:BD14)
C15: =SUM(AB15:AJ15) | D15: =SUM(AK15:AS15) | E15: =SUM(AT15:AU15) | F15: =SUM(AV15:AZ15) | G15: =SUM(BA15:BD15) | H15: =SUM(V15:AA15) | I15: =SUM(C15:H15) | R15: =R14+SUM(N15:Q15)-SUM(I15:M15) | BE15: =I15-SUM(AB15:BD15)
C16: =SUM(AB16:AJ16) | D16: =SUM(AK16:AS16) | E16: =SUM(AT16:AU16) | F16: =SUM(AV16:AZ16) | G16: =SUM(BA16:BD16) | H16: =SUM(V16:AA16) | I16: =SUM(C16:H16) | R16: =R15+SUM(N16:Q16)-SUM(I16:M16) | BE16: =I16-SUM(AB16:BD16)
... C45: =SUM(AB45:AJ45) | D45: =SUM(AK45:AS45) | E45: =SUM(AT45:AU45) | F45: =SUM(AV45:AZ45) | G45: =SUM(BA45:BD45) | H45: =SUM(V45:AA45) | I45: =SUM(C45:H45) | R45: =R44+SUM(N45:Q45)-SUM(I45:M45) | BE45: =I45-SUM(AB45:BD45)
C46: =SUM(AB46:AJ46) | D46: =SUM(AK46:AS46) | E46: =SUM(AT46:AU46) | F46: =SUM(AV46:AZ46) | G46: =SUM(BA46:BD46) | H46: =SUM(V46:AA46) | I46: =SUM(C46:H46) | R46: =R45+SUM(N46:Q46)-SUM(I46:M46)
C47: =SUM(AB47:AJ47) | D47: =SUM(AK47:AS47) | E47: =SUM(AT47:AU47) | F47: =SUM(AV47:AZ47) | G47: =SUM(BA47:BD47) | H47: =SUM(V47:AA47) | I47: =SUM(C47:H47) | R47: =R46+SUM(N47:Q47)-SUM(I47:M47) | BE47: =I47-SUM(AB47:BD47)
C48: =SUM(AB48:AJ48) | D48: =SUM(AK48:AS48) | E48: =SUM(AT48:AU48) | F48: =SUM(AV48:AZ48) | G48: =SUM(BA48:BD48) | H48: =SUM(V48:AA48) | I48: =SUM(C48:H48) | R48: =R47+SUM(N48:Q48)-SUM(I48:M48) | BE48: =I48-SUM(AB48:BD48)
C49: =SUM(AB49:AJ49) | D49: =SUM(AK49:AS49) | E49: =SUM(AT49:AU49) | F49: =SUM(AV49:AZ49) | G49: =SUM(BA49:BD49) | H49: =SUM(V49:AA49) | I49: =SUM(C49:H49) | R49: =R48+SUM(N49:Q49)-SUM(I49:M49) | BE49: =I49-SUM(AB49:BD49)
C50: =SUM(AB50:AJ50) | D50: =SUM(AK50:AS50) | E50: =SUM(AT50:AU50) | F50: =SUM(AV50:AZ50) | G50: =SUM(BA50:BD50) | H50: =SUM(V50:AA50) | I50: =SUM(C50:H50) | R50: =R49+SUM(N50:Q50)-SUM(I50:M50) | BE50: =I50-SUM(AB50:BD50)
C51: =SUM(AB51:AJ51) | D51: =SUM(AK51:AS51) | E51: =SUM(AT51:AU51) | F51: =SUM(AV51:AZ51) | G51: =SUM(BA51:BD51) | H51: =SUM(V51:AA51) | I51: =SUM(C51:H51) | R51: =R50+SUM(N51:Q51)-SUM(I51:M51) | BE51: =I51-SUM(AB51:BD51)
C52: =SUM(AB52:AJ52) | D52: =SUM(AK52:AS52) | E52: =SUM(AT52:AU52) | F52: =SUM(AV52:AZ52) | G52: =SUM(BA52:BD52) | H52: =SUM(V52:AA52) | I52: =SUM(C52:H52) | R52: =R51+SUM(N52:Q52)-SUM(I52:M52) | BE52: =I52-SUM(AB52:BD52)
C53: =SUM(AB53:AJ53) | D53: =SUM(AK53:AS53) | E53: =SUM(AT53:AU53) | F53: =SUM(AV53:AZ53) | G53: =SUM(BA53:BD53) | H53: =SUM(V53:AA53) | I53: =SUM(C53:H53) | R53: =R52+SUM(N53:Q53)-SUM(I53:M53) | BE53: =I53-SUM(AB53:BD53)
C54: =SUM(AB54:AJ54) | D54: =SUM(AK54:AS54) | E54: =SUM(AT54:AU54) | F54: =SUM(AV54:AZ54) | G54: =SUM(BA54:BD54) | H54: =SUM(V54:AA54) | I54: =SUM(C54:H54) | R54: =R53+SUM(N54:Q54)-SUM(I54:M54) | BE54: =I54-SUM(AB54:BD54)
C55: =SUM(AB55:AJ55) | D55: =SUM(AK55:AS55) | E55: =SUM(AT55:AU55) | F55: =SUM(AV55:AZ55) | G55: =SUM(BA55:BD55) | H55: =SUM(V55:AA55) | I55: =SUM(C55:H55) | R55: =R54+SUM(N55:Q55)-SUM(I55:M55) | BE55: =I55-SUM(AB55:BD55)
C56: =SUM(AB56:AJ56) | D56: =SUM(AK56:AS56) | E56: =SUM(AT56:AU56) | F56: =SUM(AV56:AZ56) | G56: =SUM(BA56:BD56) | H56: =SUM(V56:AA56) | I56: =SUM(C56:H56) | R56: =R55+SUM(N56:Q56)-SUM(I56:M56) | BE56: =I56-SUM(AB56:BD56)
C57: =SUM(AB57:AJ57) | D57: =SUM(AK57:AS57) | E57: =SUM(AT57:AU57) | F57: =SUM(AV57:AZ57) | G57: =SUM(BA57:BD57) | H57: =SUM(V57:AA57) | I57: =SUM(C57:H57) | R57: =R56+SUM(N57:Q57)-SUM(I57:M57) | BE57: =I57-SUM(AB57:BD57)
C58: =SUM(AB58:AJ58) | D58: =SUM(AK58:AS58) | E58: =SUM(AT58:AU58) | F58: =SUM(AV58:AZ58) | G58: =SUM(BA58:BD58) | H58: =SUM(V58:AA58) | I58: =SUM(C58:H58) | R58: =R57+SUM(N58:Q58)-SUM(I58:M58) | BE58: =I58-SUM(AB58:BD58)
... C113: =SUM(AB113:AJ113) | D113: =SUM(AK113:AS113) | E113: =SUM(AT113:AU113) | F113: =SUM(AV113:AZ113) | G113: =SUM(BA113:BD113) | H113: =SUM(V113:AA113) | I113: =SUM(C113:H113) | R113: =R112+SUM(N113:Q113)-SUM(I113:M113) | BE113: =I113-SUM(AB113:BD113)
A114: 合计 | C114: =SUM(C5:C113) | D114: =SUM(D5:D113) | E114: =SUM(E5:E113) | F114: =SUM(F5:F113) | G114: =SUM(G5:G113) | H114: =SUM(H5:H113) | I114: =SUM(I5:I113) | J114: =SUM(J5:J113) | ... N114: =SUM(N5:N113) | P114: =SUM(P5:P113) | Q114: =SUM(Q5:Q113) | R114: =R4+N114+P114+Q114-M114-L114-K114-J114-I114 | V114: =SUM(V5:V113) | W114: =SUM(W5:W113) | X114: =SUM(X5:X113) | Y114: =SUM(Y5:Y113) | Z114: =SUM(Z5:Z113) | AA114: =SUM(AA5:AA113) | AB114: =SUM(AB5:AB113) | AC114: =SUM(AC5:AC113) | ... BD114: =SUM(BD5:BD113) | BE114: =I114-SUM(AB114:BD114)
A115: SPD-5465-理财产品期初余额 | I115: =SUM(C115:H115) | R115: =R114+SUM(N115:Q115)-SUM(I115:M115)
C116: =SUM(AB116:AJ116) | D116: =SUM(AK116:AS116) | E116: =SUM(AT116:AU116) | F116: =SUM(AV116:AZ116) | G116: =SUM(BA116:BD116) | H116: =SUM(V116:AA116) | I116: =SUM(C116:H116) | R116: =R115+SUM(N116:Q116)-SUM(I116:M116) | BE116: =I116-SUM(AB116:BD116)
C117: =SUM(AB117:AJ117) | D117: =SUM(AK117:AS117) | E117: =SUM(AT117:AU117) | F117: =SUM(AV117:AZ117) | G117: =SUM(BA117:BD117) | H117: =SUM(V117:AA117) | I117: =SUM(C117:H117) | R117: =R116+SUM(N117:Q117)-SUM(I117:M117) | BE117: =I117-SUM(AB117:BD117)
C118: =SUM(AB118:AJ118) | D118: =SUM(AK118:AS118) | E118: =SUM(AT118:AU118) | F118: =SUM(AV118:AZ118) | G118: =SUM(BA118:BD118) | H118: =SUM(V118:AA118) | I118: =SUM(C118:H118) | R118: =R117+SUM(N118:Q118)-SUM(I118:M118) | BE118: =I118-SUM(AB118:BD118)
R119: =R118+SUM(N119:Q119)-SUM(I119:M119)
C120: =SUM(AB120:AJ120) | D120: =SUM(AK120:AS120) | E120: =SUM(AT120:AU120) | F120: =SUM(AV120:AZ120) | G120: =SUM(BA120:BD120) | H120: =SUM(V120:AA120) | I120: =SUM(C120:H120) | R120: =R119+SUM(N120:Q120)-SUM(I120:M120) | BE120: =I120-SUM(AB120:BD120)
R121: =R120+SUM(N121:Q121)-SUM(I121:M121)
A122: SFD-5465-理财产品小计 | C122: =SUM(C116:C120) | D122: =SUM(D116:D120) | E122: =SUM(E116:E120) | F122: =SUM(F116:F120) | G122: =SUM(G116:G120) | H122: =SUM(H116:H120) | I122: =SUM(I116:I120) | J122: =SUM(J116:J120) | K122: =SUM(K116:K121) | L122: =SUM(L116:L120) | M122: =SUM(M116:M120) | N122: =SUM(N116:N120) | P122: =SUM(P116:P120) | Q122: =SUM(Q116:Q120) | R122: =R121+SUM(N122:Q122)-SUM(I122:M122) | V122: =SUM(V116:V120) | X122: =SUM(X116:X120) | Z122: =SUM(Z116:Z120) | AA122: =SUM(AA116:AA120) | AB122: =SUM(AB116:AB120) | AD122: =SUM(AD116:AD120) | AE122: =SUM(AE116:AE120) | AF122: =SUM(AF116:AF120) | AG122: =SUM(AG116:AG120) | AH122: =SUM(AH116:AH120) | AI122: =SUM(AI116:AI120) | AJ122: =SUM(AJ116:AJ120) | AK122: =SUM(AK116:AK120) | ... BD122: =SUM(BD116:BD120) | BE122: =I122-SUM(AB122:BD122)

Sheet 4、账户
A1: ←返回
A2: 行号 | B2: 交易时间 | C2: 销售费用 | D2: 管理费用 | E2: 财务费用 | F2: 应缴税金 | G2: 固定资产 | H2: 主营业务支出 | I2: 日常支出和 | J2: 集团往来 | K2: 理财 | L2: 提现 | M2: 押金/暂支款 | N2: 收入 | R2: 余额 | S2: 客户/供应商 | T2: 部门 | U2: 摘要 | V2: 主营业务支出 | AB2: 销售费用 | AK2: 管理费用 | AT2: 财务费用 | AV2: 应缴税金 | BA2: 有形资产
N3: 常年咨询服务 | O3: 涉税专项服务 | P3: 财税外包服务 | Q3: 企业培训服务 | V3: 服务费 | W3: 推广费 | X3: 佣金 | Y3: 劳务费 | Z3: 分成 | AA3: 其他 | AB3: 市场宣传 | AC3: 市场辅料 | AD3: 飞机、动车等 | AE3: 住宿费 | AF3: 车辆费 | AG3: 市内交通 | AH3: 招待/公关 | AI3: 服务费 | AJ3: 其他 | AK3: 办公用品&办公费 | AL3: 办公租金&物业费 | AM3: 交通费 | AN3: 招待费 | AO3: 服务费 | AP3: 人员薪资 | AQ3: 社保&公积金 | AR3: 员工福利 | AS3: 其他 | AT3: 手续费 | AU3: 利息 | AV3: 增值税及附加 | AW3: 所得税 | AX3: 印花税 | AY3: 工资个税 | AZ3: 劳务个税 | BA3: 办公设备 | BB3: 办公家具 (包含车等）
A4: XX期初余额 | I4: 0 | R4: 0
C5: =SUM(AB5:AJ5) | D5: =SUM(AK5:AS5) | E5: =SUM(AT5:AU5) | F5: =SUM(AV5:AZ5) | G5: =SUM(BA5:BD5) | H5: =SUM(V5:AA5) | I5: =SUM(C5:H5) | R5: =R4+SUM(N5:Q5)-SUM(I5:M5) | BE5: =I5-SUM(AB5:BD5)
C6: =SUM(AB6:AJ6) | D6: =SUM(AK6:AS6) | E6: =SUM(AT6:AU6) | F6: =SUM(AV6:AZ6) | G6: =SUM(BA6:BD6) | H6: =SUM(V6:AA6) | I6: =SUM(C6:H6) | R6: =R5+SUM(N6:Q6)-SUM(I6:M6) | BE6: =I6-SUM(AB6:BD6)
C7: =SUM(AB7:AJ7) | D7: =SUM(AK7:AS7) | E7: =SUM(AT7:AU7) | F7: =SUM(AV7:AZ7) | G7: =SUM(BA7:BD7) | H7: =SUM(V7:AA7) | I7: =SUM(C7:H7) | R7: =R6+SUM(N7:Q7)-SUM(I7:M7) | BE7: =I7-SUM(AB7:BD7)
C8: =SUM(AB8:AJ8) | D8: =SUM(AK8:AS8) | E8: =SUM(AT8:AU8) | F8: =SUM(AV8:AZ8) | G8: =SUM(BA8:BD8) | H8: =SUM(V8:AA8) | I8: =SUM(C8:H8) | R8: =R7+SUM(N8:Q8)-SUM(I8:M8) | BE8: =I8-SUM(AB8:BD8)
C9: =SUM(AB9:AJ9) | D9: =SUM(AK9:AS9) | E9: =SUM(AT9:AU9) | F9: =SUM(AV9:AZ9) | G9: =SUM(BA9:BD9) | H9: =SUM(V9:AA9) | I9: =SUM(C9:H9) | R9: =R8+SUM(N9:Q9)-SUM(I9:M9) | BE9: =I9-SUM(AB9:BD9)
C10: =SUM(AB10:AJ10) | D10: =SUM(AK10:AS10) | E10: =SUM(AT10:AU10) | F10: =SUM(AV10:AZ10) | G10: =SUM(BA10:BD10) | H10: =SUM(V10:AA10) | I10: =SUM(C10:H10) | R10: =R9+SUM(N10:Q10)-SUM(I10:M10) | BE10: =I10-SUM(AB10:BD10)
C11: =SUM(AB11:AJ11) | D11: =SUM(AK11:AS11) | E11: =SUM(AT11:AU11) | F11: =SUM(AV11:AZ11) | G11: =SUM(BA11:BD11) | H11: =SUM(V11:AA11) | I11: =SUM(C11:H11) | R11: =R10+SUM(N11:Q11)-SUM(I11:M11) | BE11: =I11-SUM(AB11:BD11)
C12: =SUM(AB12:AJ12) | D12: =SUM(AK12:AS12) | E12: =SUM(AT12:AU12) | F12: =SUM(AV12:AZ12) | G12: =SUM(BA12:BD12) | H12: =SUM(V12:AA12) | I12: =SUM(C12:H12) | R12: =R11+SUM(N12:Q12)-SUM(I12:M12) | BE12: =I12-SUM(AB12:BD12)
C13: =SUM(AB13:AJ13) | D13: =SUM(AK13:AS13) | E13: =SUM(AT13:AU13) | F13: =SUM(AV13:AZ13) | G13: =SUM(BA13:BD13) | H13: =SUM(V13:AA13) | I13: =SUM(C13:H13) | R13: =R12+SUM(N13:Q13)-SUM(I13:M13) | BE13: =I13-SUM(AB13:BD13)
C14: =SUM(AB14:AJ14) | D14: =SUM(AK14:AS14) | E14: =SUM(AT14:AU14) | F14: =SUM(AV14:AZ14) | G14: =SUM(BA14:BD14) | H14: =SUM(V14:AA14) | I14: =SUM(C14:H14) | R14: =R13+SUM(N14:Q14)-SUM(I14:M14) | BE14: =I14-SUM(AB14:BD14)
C15: =SUM(AB15:AJ15) | D15: =SUM(AK15:AS15) | E15: =SUM(AT15:AU15) | F15: =SUM(AV15:AZ15) | G15: =SUM(BA15:BD15) | H15: =SUM(V15:AA15) | I15: =SUM(C15:H15) | R15: =R14+SUM(N15:Q15)-SUM(I15:M15) | BE15: =I15-SUM(AB15:BD15)
C16: =SUM(AB16:AJ16) | D16: =SUM(AK16:AS16) | E16: =SUM(AT16:AU16) | F16: =SUM(AV16:AZ16) | G16: =SUM(BA16:BD16) | H16: =SUM(V16:AA16) | I16: =SUM(C16:H16) | R16: =R15+SUM(N16:Q16)-SUM(I16:M16) | BE16: =I16-SUM(AB16:BD16)
... C45: =SUM(AB45:AJ45) | D45: =SUM(AK45:AS45) | E45: =SUM(AT45:AU45) | F45: =SUM(AV45:AZ45) | G45: =SUM(BA45:BD45) | H45: =SUM(V45:AA45) | I45: =SUM(C45:H45) | R45: =R44+SUM(N45:Q45)-SUM(I45:M45) | BE45: =I45-SUM(AB45:BD45)
C46: =SUM(AB46:AJ46) | D46: =SUM(AK46:AS46) | E46: =SUM(AT46:AU46) | F46: =SUM(AV46:AZ46) | G46: =SUM(BA46:BD46) | H46: =SUM(V46:AA46) | I46: =SUM(C46:H46) | R46: =R45+SUM(N46:Q46)-SUM(I46:M46)
C47: =SUM(AB47:AJ47) | D47: =SUM(AK47:AS47) | E47: =SUM(AT47:AU47) | F47: =SUM(AV47:AZ47) | G47: =SUM(BA47:BD47) | H47: =SUM(V47:AA47) | I47: =SUM(C47:H47) | R47: =R46+SUM(N47:Q47)-SUM(I47:M47) | BE47: =I47-SUM(AB47:BD47)
C48: =SUM(AB48:AJ48) | D48: =SUM(AK48:AS48) | E48: =SUM(AT48:AU48) | F48: =SUM(AV48:AZ48) | G48: =SUM(BA48:BD48) | H48: =SUM(V48:AA48) | I48: =SUM(C48:H48) | R48: =R47+SUM(N48:Q48)-SUM(I48:M48) | BE48: =I48-SUM(AB48:BD48)
C49: =SUM(AB49:AJ49) | D49: =SUM(AK49:AS49) | E49: =SUM(AT49:AU49) | F49: =SUM(AV49:AZ49) | G49: =SUM(BA49:BD49) | H49: =SUM(V49:AA49) | I49: =SUM(C49:H49) | R49: =R48+SUM(N49:Q49)-SUM(I49:M49) | BE49: =I49-SUM(AB49:BD49)
C50: =SUM(AB50:AJ50) | D50: =SUM(AK50:AS50) | E50: =SUM(AT50:AU50) | F50: =SUM(AV50:AZ50) | G50: =SUM(BA50:BD50) | H50: =SUM(V50:AA50) | I50: =SUM(C50:H50) | R50: =R49+SUM(N50:Q50)-SUM(I50:M50) | BE50: =I50-SUM(AB50:BD50)
C51: =SUM(AB51:AJ51) | D51: =SUM(AK51:AS51) | E51: =SUM(AT51:AU51) | F51: =SUM(AV51:AZ51) | G51: =SUM(BA51:BD51) | H51: =SUM(V51:AA51) | I51: =SUM(C51:H51) | R51: =R50+SUM(N51:Q51)-SUM(I51:M51) | BE51: =I51-SUM(AB51:BD51)
C52: =SUM(AB52:AJ52) | D52: =SUM(AK52:AS52) | E52: =SUM(AT52:AU52) | F52: =SUM(AV52:AZ52) | G52: =SUM(BA52:BD52) | H52: =SUM(V52:AA52) | I52: =SUM(C52:H52) | R52: =R51+SUM(N52:Q52)-SUM(I52:M52) | BE52: =I52-SUM(AB52:BD52)
C53: =SUM(AB53:AJ53) | D53: =SUM(AK53:AS53) | E53: =SUM(AT53:AU53) | F53: =SUM(AV53:AZ53) | G53: =SUM(BA53:BD53) | H53: =SUM(V53:AA53) | I53: =SUM(C53:H53) | R53: =R52+SUM(N53:Q53)-SUM(I53:M53) | BE53: =I53-SUM(AB53:BD53)
C54: =SUM(AB54:AJ54) | D54: =SUM(AK54:AS54) | E54: =SUM(AT54:AU54) | F54: =SUM(AV54:AZ54) | G54: =SUM(BA54:BD54) | H54: =SUM(V54:AA54) | I54: =SUM(C54:H54) | R54: =R53+SUM(N54:Q54)-SUM(I54:M54) | BE54: =I54-SUM(AB54:BD54)
C55: =SUM(AB55:AJ55) | D55: =SUM(AK55:AS55) | E55: =SUM(AT55:AU55) | F55: =SUM(AV55:AZ55) | G55: =SUM(BA55:BD55) | H55: =SUM(V55:AA55) | I55: =SUM(C55:H55) | R55: =R54+SUM(N55:Q55)-SUM(I55:M55) | BE55: =I55-SUM(AB55:BD55)
C56: =SUM(AB56:AJ56) | D56: =SUM(AK56:AS56) | E56: =SUM(AT56:AU56) | F56: =SUM(AV56:AZ56) | G56: =SUM(BA56:BD56) | H56: =SUM(V56:AA56) | I56: =SUM(C56:H56) | R56: =R55+SUM(N56:Q56)-SUM(I56:M56) | BE56: =I56-SUM(AB56:BD56)
C57: =SUM(AB57:AJ57) | D57: =SUM(AK57:AS57) | E57: =SUM(AT57:AU57) | F57: =SUM(AV57:AZ57) | G57: =SUM(BA57:BD57) | H57: =SUM(V57:AA57) | I57: =SUM(C57:H57) | R57: =R56+SUM(N57:Q57)-SUM(I57:M57) | BE57: =I57-SUM(AB57:BD57)
C58: =SUM(AB58:AJ58) | D58: =SUM(AK58:AS58) | E58: =SUM(AT58:AU58) | F58: =SUM(AV58:AZ58) | G58: =SUM(BA58:BD58) | H58: =SUM(V58:AA58) | I58: =SUM(C58:H58) | R58: =R57+SUM(N58:Q58)-SUM(I58:M58) | BE58: =I58-SUM(AB58:BD58)
... C113: =SUM(AB113:AJ113) | D113: =SUM(AK113:AS113) | E113: =SUM(AT113:AU113) | F113: =SUM(AV113:AZ113) | G113: =SUM(BA113:BD113) | H113: =SUM(V113:AA113) | I113: =SUM(C113:H113) | R113: =R112+SUM(N113:Q113)-SUM(I113:M113) | BE113: =I113-SUM(AB113:BD113)
A114: 合计 | C114: =SUM(C5:C113) | D114: =SUM(D5:D113) | E114: =SUM(E5:E113) | F114: =SUM(F5:F113) | G114: =SUM(G5:G113) | H114: =SUM(H5:H113) | I114: =SUM(I5:I113) | J114: =SUM(J5:J113) | ... N114: =SUM(N5:N113) | P114: =SUM(P5:P113) | Q114: =SUM(Q5:Q113) | R114: =R4+N114+P114+Q114-M114-L114-K114-J114-I114 | V114: =SUM(V5:V113) | W114: =SUM(W5:W113) | X114: =SUM(X5:X113) | Y114: =SUM(Y5:Y113) | Z114: =SUM(Z5:Z113) | AA114: =SUM(AA5:AA113) | AB114: =SUM(AB5:AB113) | AC114: =SUM(AC5:AC113) | ... BD114: =SUM(BD5:BD113) | BE114: =I114-SUM(AB114:BD114)
A115: SPD-5465-理财产品期初余额 | I115: =SUM(C115:H115) | R115: =R114+SUM(N115:Q115)-SUM(I115:M115)
C116: =SUM(AB116:AJ116) | D116: =SUM(AK116:AS116) | E116: =SUM(AT116:AU116) | F116: =SUM(AV116:AZ116) | G116: =SUM(BA116:BD116) | H116: =SUM(V116:AA116) | I116: =SUM(C116:H116) | R116: =R115+SUM(N116:Q116)-SUM(I116:M116) | BE116: =I116-SUM(AB116:BD116)
C117: =SUM(AB117:AJ117) | D117: =SUM(AK117:AS117) | E117: =SUM(AT117:AU117) | F117: =SUM(AV117:AZ117) | G117: =SUM(BA117:BD117) | H117: =SUM(V117:AA117) | I117: =SUM(C117:H117) | R117: =R116+SUM(N117:Q117)-SUM(I117:M117) | BE117: =I117-SUM(AB117:BD117)
C118: =SUM(AB118:AJ118) | D118: =SUM(AK118:AS118) | E118: =SUM(AT118:AU118) | F118: =SUM(AV118:AZ118) | G118: =SUM(BA118:BD118) | H118: =SUM(V118:AA118) | I118: =SUM(C118:H118) | R118: =R117+SUM(N118:Q118)-SUM(I118:M118) | BE118: =I118-SUM(AB118:BD118)
R119: =R118+SUM(N119:Q119)-SUM(I119:M119)
C120: =SUM(AB120:AJ120) | D120: =SUM(AK120:AS120) | E120: =SUM(AT120:AU120) | F120: =SUM(AV120:AZ120) | G120: =SUM(BA120:BD120) | H120: =SUM(V120:AA120) | I120: =SUM(C120:H120) | R120: =R119+SUM(N120:Q120)-SUM(I120:M120) | BE120: =I120-SUM(AB120:BD120)
R121: =R120+SUM(N121:Q121)-SUM(I121:M121)
A122: SFD-5465-理财产品小计 | C122: =SUM(C116:C120) | D122: =SUM(D116:D120) | E122: =SUM(E116:E120) | F122: =SUM(F116:F120) | G122: =SUM(G116:G120) | H122: =SUM(H116:H120) | I122: =SUM(I116:I120) | J122: =SUM(J116:J120) | K122: =SUM(K116:K121) | L122: =SUM(L116:L120) | M122: =SUM(M116:M120) | N122: =SUM(N116:N120) | P122: =SUM(P116:P120) | Q122: =SUM(Q116:Q120) | R122: =R121+SUM(N122:Q122)-SUM(I122:M122) | V122: =SUM(V116:V120) | X122: =SUM(X116:X120) | Z122: =SUM(Z116:Z120) | AA122: =SUM(AA116:AA120) | AB122: =SUM(AB116:AB120) | AD122: =SUM(AD116:AD120) | AE122: =SUM(AE116:AE120) | AF122: =SUM(AF116:AF120) | AG122: =SUM(AG116:AG120) | AH122: =SUM(AH116:AH120) | AI122: =SUM(AI116:AI120) | AJ122: =SUM(AJ116:AJ120) | AK122: =SUM(AK116:AK120) | ... BD122: =SUM(BD116:BD120) | BE122: =I122-SUM(AB122:BD122)

Sheet 5、支付宝
A1: ←返回
A2: 行号 | B2: 交易时间 | C2: 销售费用 | D2: 管理费用 | E2: 财务费用 | F2: 应缴税金 | G2: 固定资产 | H2: 主营业务支出 | I2: 日常支出和 | J2: 集团往来 | K2: 理财 | L2: 提现 | M2: 押金/暂支款 | N2: 收入 | R2: 余额 | S2: 客户/供应商 | T2: 部门 | U2: 摘要 | V2: 主营业务支出 | AB2: 销售费用 | AK2: 管理费用 | AT2: 财务费用 | AV2: 应缴税金 | BA2: 有形资产
N3: 常年咨询服务 | O3: 涉税专项服务 | P3: 财税外包服务 | Q3: 企业培训服务 | V3: 服务费 | W3: 推广费 | X3: 佣金 | Y3: 劳务费 | Z3: 分成 | AA3: 其他 | AB3: 市场宣传 | AC3: 市场辅料 | AD3: 飞机、动车等 | AE3: 住宿费 | AF3: 车辆费 | AG3: 市内交通 | AH3: 招待/公关 | AI3: 服务费 | AJ3: 其他 | AK3: 办公用品&办公费 | AL3: 办公租金&物业费 | AM3: 交通费 | AN3: 招待费 | AO3: 服务费 | AP3: 人员薪资 | AQ3: 社保&公积金 | AR3: 员工福利 | AS3: 其他 | AT3: 手续费 | AU3: 利息 | AV3: 增值税及附加 | AW3: 所得税 | AX3: 印花税 | AY3: 工资个税 | AZ3: 劳务个税 | BA3: 办公设备 | BB3: 办公家具 (包含车等）
A4: XX期初余额 | I4: 0 | R4: 0
C5: =SUM(AB5:AJ5) | D5: =SUM(AK5:AS5) | E5: =SUM(AT5:AU5) | F5: =SUM(AV5:AZ5) | G5: =SUM(BA5:BD5) | H5: =SUM(V5:AA5) | I5: =SUM(C5:H5) | R5: =R4+SUM(N5:Q5)-SUM(I5:M5) | BE5: =I5-SUM(AB5:BD5)
C6: =SUM(AB6:AJ6) | D6: =SUM(AK6:AS6) | E6: =SUM(AT6:AU6) | F6: =SUM(AV6:AZ6) | G6: =SUM(BA6:BD6) | H6: =SUM(V6:AA6) | I6: =SUM(C6:H6) | R6: =R5+SUM(N6:Q6)-SUM(I6:M6) | BE6: =I6-SUM(AB6:BD6)
C7: =SUM(AB7:AJ7) | D7: =SUM(AK7:AS7) | E7: =SUM(AT7:AU7) | F7: =SUM(AV7:AZ7) | G7: =SUM(BA7:BD7) | H7: =SUM(V7:AA7) | I7: =SUM(C7:H7) | R7: =R6+SUM(N7:Q7)-SUM(I7:M7) | BE7: =I7-SUM(AB7:BD7)
C8: =SUM(AB8:AJ8) | D8: =SUM(AK8:AS8) | E8: =SUM(AT8:AU8) | F8: =SUM(AV8:AZ8) | G8: =SUM(BA8:BD8) | H8: =SUM(V8:AA8) | I8: =SUM(C8:H8) | R8: =R7+SUM(N8:Q8)-SUM(I8:M8) | BE8: =I8-SUM(AB8:BD8)
C9: =SUM(AB9:AJ9) | D9: =SUM(AK9:AS9) | E9: =SUM(AT9:AU9) | F9: =SUM(AV9:AZ9) | G9: =SUM(BA9:BD9) | H9: =SUM(V9:AA9) | I9: =SUM(C9:H9) | R9: =R8+SUM(N9:Q9)-SUM(I9:M9) | BE9: =I9-SUM(AB9:BD9)
C10: =SUM(AB10:AJ10) | D10: =SUM(AK10:AS10) | E10: =SUM(AT10:AU10) | F10: =SUM(AV10:AZ10) | G10: =SUM(BA10:BD10) | H10: =SUM(V10:AA10) | I10: =SUM(C10:H10) | R10: =R9+SUM(N10:Q10)-SUM(I10:M10) | BE10: =I10-SUM(AB10:BD10)
C11: =SUM(AB11:AJ11) | D11: =SUM(AK11:AS11) | E11: =SUM(AT11:AU11) | F11: =SUM(AV11:AZ11) | G11: =SUM(BA11:BD11) | H11: =SUM(V11:AA11) | I11: =SUM(C11:H11) | R11: =R10+SUM(N11:Q11)-SUM(I11:M11) | BE11: =I11-SUM(AB11:BD11)
C12: =SUM(AB12:AJ12) | D12: =SUM(AK12:AS12) | E12: =SUM(AT12:AU12) | F12: =SUM(AV12:AZ12) | G12: =SUM(BA12:BD12) | H12: =SUM(V12:AA12) | I12: =SUM(C12:H12) | R12: =R11+SUM(N12:Q12)-SUM(I12:M12) | BE12: =I12-SUM(AB12:BD12)
C13: =SUM(AB13:AJ13) | D13: =SUM(AK13:AS13) | E13: =SUM(AT13:AU13) | F13: =SUM(AV13:AZ13) | G13: =SUM(BA13:BD13) | H13: =SUM(V13:AA13) | I13: =SUM(C13:H13) | R13: =R12+SUM(N13:Q13)-SUM(I13:M13) | BE13: =I13-SUM(AB13:BD13)
C14: =SUM(AB14:AJ14) | D14: =SUM(AK14:AS14) | E14: =SUM(AT14:AU14) | F14: =SUM(AV14:AZ14) | G14: =SUM(BA14:BD14) | H14: =SUM(V14:AA14) | I14: =SUM(C14:H14) | R14: =R13+SUM(N14:Q14)-SUM(I14:M14) | BE14: =I14-SUM(AB14:BD14)
C15: =SUM(AB15:AJ15) | D15: =SUM(AK15:AS15) | E15: =SUM(AT15:AU15) | F15: =SUM(AV15:AZ15) | G15: =SUM(BA15:BD15) | H15: =SUM(V15:AA15) | I15: =SUM(C15:H15) | R15: =R14+SUM(N15:Q15)-SUM(I15:M15) | BE15: =I15-SUM(AB15:BD15)
C16: =SUM(AB16:AJ16) | D16: =SUM(AK16:AS16) | E16: =SUM(AT16:AU16) | F16: =SUM(AV16:AZ16) | G16: =SUM(BA16:BD16) | H16: =SUM(V16:AA16) | I16: =SUM(C16:H16) | R16: =R15+SUM(N16:Q16)-SUM(I16:M16) | BE16: =I16-SUM(AB16:BD16)
... C45: =SUM(AB45:AJ45) | D45: =SUM(AK45:AS45) | E45: =SUM(AT45:AU45) | F45: =SUM(AV45:AZ45) | G45: =SUM(BA45:BD45) | H45: =SUM(V45:AA45) | I45: =SUM(C45:H45) | R45: =R44+SUM(N45:Q45)-SUM(I45:M45) | BE45: =I45-SUM(AB45:BD45)
C46: =SUM(AB46:AJ46) | D46: =SUM(AK46:AS46) | E46: =SUM(AT46:AU46) | F46: =SUM(AV46:AZ46) | G46: =SUM(BA46:BD46) | H46: =SUM(V46:AA46) | I46: =SUM(C46:H46) | R46: =R45+SUM(N46:Q46)-SUM(I46:M46)
C47: =SUM(AB47:AJ47) | D47: =SUM(AK47:AS47) | E47: =SUM(AT47:AU47) | F47: =SUM(AV47:AZ47) | G47: =SUM(BA47:BD47) | H47: =SUM(V47:AA47) | I47: =SUM(C47:H47) | R47: =R46+SUM(N47:Q47)-SUM(I47:M47) | BE47: =I47-SUM(AB47:BD47)
C48: =SUM(AB48:AJ48) | D48: =SUM(AK48:AS48) | E48: =SUM(AT48:AU48) | F48: =SUM(AV48:AZ48) | G48: =SUM(BA48:BD48) | H48: =SUM(V48:AA48) | I48: =SUM(C48:H48) | R48: =R47+SUM(N48:Q48)-SUM(I48:M48) | BE48: =I48-SUM(AB48:BD48)
C49: =SUM(AB49:AJ49) | D49: =SUM(AK49:AS49) | E49: =SUM(AT49:AU49) | F49: =SUM(AV49:AZ49) | G49: =SUM(BA49:BD49) | H49: =SUM(V49:AA49) | I49: =SUM(C49:H49) | R49: =R48+SUM(N49:Q49)-SUM(I49:M49) | BE49: =I49-SUM(AB49:BD49)
C50: =SUM(AB50:AJ50) | D50: =SUM(AK50:AS50) | E50: =SUM(AT50:AU50) | F50: =SUM(AV50:AZ50) | G50: =SUM(BA50:BD50) | H50: =SUM(V50:AA50) | I50: =SUM(C50:H50) | R50: =R49+SUM(N50:Q50)-SUM(I50:M50) | BE50: =I50-SUM(AB50:BD50)
C51: =SUM(AB51:AJ51) | D51: =SUM(AK51:AS51) | E51: =SUM(AT51:AU51) | F51: =SUM(AV51:AZ51) | G51: =SUM(BA51:BD51) | H51: =SUM(V51:AA51) | I51: =SUM(C51:H51) | R51: =R50+SUM(N51:Q51)-SUM(I51:M51) | BE51: =I51-SUM(AB51:BD51)
C52: =SUM(AB52:AJ52) | D52: =SUM(AK52:AS52) | E52: =SUM(AT52:AU52) | F52: =SUM(AV52:AZ52) | G52: =SUM(BA52:BD52) | H52: =SUM(V52:AA52) | I52: =SUM(C52:H52) | R52: =R51+SUM(N52:Q52)-SUM(I52:M52) | BE52: =I52-SUM(AB52:BD52)
C53: =SUM(AB53:AJ53) | D53: =SUM(AK53:AS53) | E53: =SUM(AT53:AU53) | F53: =SUM(AV53:AZ53) | G53: =SUM(BA53:BD53) | H53: =SUM(V53:AA53) | I53: =SUM(C53:H53) | R53: =R52+SUM(N53:Q53)-SUM(I53:M53) | BE53: =I53-SUM(AB53:BD53)
C54: =SUM(AB54:AJ54) | D54: =SUM(AK54:AS54) | E54: =SUM(AT54:AU54) | F54: =SUM(AV54:AZ54) | G54: =SUM(BA54:BD54) | H54: =SUM(V54:AA54) | I54: =SUM(C54:H54) | R54: =R53+SUM(N54:Q54)-SUM(I54:M54) | BE54: =I54-SUM(AB54:BD54)
C55: =SUM(AB55:AJ55) | D55: =SUM(AK55:AS55) | E55: =SUM(AT55:AU55) | F55: =SUM(AV55:AZ55) | G55: =SUM(BA55:BD55) | H55: =SUM(V55:AA55) | I55: =SUM(C55:H55) | R55: =R54+SUM(N55:Q55)-SUM(I55:M55) | BE55: =I55-SUM(AB55:BD55)
C56: =SUM(AB56:AJ56) | D56: =SUM(AK56:AS56) | E56: =SUM(AT56:AU56) | F56: =SUM(AV56:AZ56) | G56: =SUM(BA56:BD56) | H56: =SUM(V56:AA56) | I56: =SUM(C56:H56) | R56: =R55+SUM(N56:Q56)-SUM(I56:M56) | BE56: =I56-SUM(AB56:BD56)
C57: =SUM(AB57:AJ57) | D57: =SUM(AK57:AS57) | E57: =SUM(AT57:AU57) | F57: =SUM(AV57:AZ57) | G57: =SUM(BA57:BD57) | H57: =SUM(V57:AA57) | I57: =SUM(C57:H57) | R57: =R56+SUM(N57:Q57)-SUM(I57:M57) | BE57: =I57-SUM(AB57:BD57)
C58: =SUM(AB58:AJ58) | D58: =SUM(AK58:AS58) | E58: =SUM(AT58:AU58) | F58: =SUM(AV58:AZ58) | G58: =SUM(BA58:BD58) | H58: =SUM(V58:AA58) | I58: =SUM(C58:H58) | R58: =R57+SUM(N58:Q58)-SUM(I58:M58) | BE58: =I58-SUM(AB58:BD58)
... C113: =SUM(AB113:AJ113) | D113: =SUM(AK113:AS113) | E113: =SUM(AT113:AU113) | F113: =SUM(AV113:AZ113) | G113: =SUM(BA113:BD113) | H113: =SUM(V113:AA113) | I113: =SUM(C113:H113) | R113: =R112+SUM(N113:Q113)-SUM(I113:M113) | BE113: =I113-SUM(AB113:BD113)
A114: 合计 | C114: =SUM(C5:C113) | D114: =SUM(D5:D113) | E114: =SUM(E5:E113) | F114: =SUM(F5:F113) | G114: =SUM(G5:G113) | H114: =SUM(H5:H113) | I114: =SUM(I5:I113) | J114: =SUM(J5:J113) | ... N114: =SUM(N5:N113) | P114: =SUM(P5:P113) | Q114: =SUM(Q5:Q113) | R114: =R4+N114+P114+Q114-M114-L114-K114-J114-I114 | V114: =SUM(V5:V113) | W114: =SUM(W5:W113) | X114: =SUM(X5:X113) | Y114: =SUM(Y5:Y113) | Z114: =SUM(Z5:Z113) | AA114: =SUM(AA5:AA113) | AB114: =SUM(AB5:AB113) | AC114: =SUM(AC5:AC113) | ... BD114: =SUM(BD5:BD113) | BE114: =I114-SUM(AB114:BD114)
A115: SPD-5465-理财产品期初余额 | I115: =SUM(C115:H115) | R115: =R114+SUM(N115:Q115)-SUM(I115:M115)
C116: =SUM(AB116:AJ116) | D116: =SUM(AK116:AS116) | E116: =SUM(AT116:AU116) | F116: =SUM(AV116:AZ116) | G116: =SUM(BA116:BD116) | H116: =SUM(V116:AA116) | I116: =SUM(C116:H116) | R116: =R115+SUM(N116:Q116)-SUM(I116:M116) | BE116: =I116-SUM(AB116:BD116)
C117: =SUM(AB117:AJ117) | D117: =SUM(AK117:AS117) | E117: =SUM(AT117:AU117) | F117: =SUM(AV117:AZ117) | G117: =SUM(BA117:BD117) | H117: =SUM(V117:AA117) | I117: =SUM(C117:H117) | R117: =R116+SUM(N117:Q117)-SUM(I117:M117) | BE117: =I117-SUM(AB117:BD117)
C118: =SUM(AB118:AJ118) | D118: =SUM(AK118:AS118) | E118: =SUM(AT118:AU118) | F118: =SUM(AV118:AZ118) | G118: =SUM(BA118:BD118) | H118: =SUM(V118:AA118) | I118: =SUM(C118:H118) | R118: =R117+SUM(N118:Q118)-SUM(I118:M118) | BE118: =I118-SUM(AB118:BD118)
R119: =R118+SUM(N119:Q119)-SUM(I119:M119)
C120: =SUM(AB120:AJ120) | D120: =SUM(AK120:AS120) | E120: =SUM(AT120:AU120) | F120: =SUM(AV120:AZ120) | G120: =SUM(BA120:BD120) | H120: =SUM(V120:AA120) | I120: =SUM(C120:H120) | R120: =R119+SUM(N120:Q120)-SUM(I120:M120) | BE120: =I120-SUM(AB120:BD120)
R121: =R120+SUM(N121:Q121)-SUM(I121:M121)
A122: SFD-5465-理财产品小计 | C122: =SUM(C116:C120) | D122: =SUM(D116:D120) | E122: =SUM(E116:E120) | F122: =SUM(F116:F120) | G122: =SUM(G116:G120) | H122: =SUM(H116:H120) | I122: =SUM(I116:I120) | J122: =SUM(J116:J120) | K122: =SUM(K116:K121) | L122: =SUM(L116:L120) | M122: =SUM(M116:M120) | N122: =SUM(N116:N120) | P122: =SUM(P116:P120) | Q122: =SUM(Q116:Q120) | R122: =R121+SUM(N122:Q122)-SUM(I122:M122) | V122: =SUM(V116:V120) | X122: =SUM(X116:X120) | Z122: =SUM(Z116:Z120) | AA122: =SUM(AA116:AA120) | AB122: =SUM(AB116:AB120) | AD122: =SUM(AD116:AD120) | AE122: =SUM(AE116:AE120) | AF122: =SUM(AF116:AF120) | AG122: =SUM(AG116:AG120) | AH122: =SUM(AH116:AH120) | AI122: =SUM(AI116:AI120) | AJ122: =SUM(AJ116:AJ120) | AK122: =SUM(AK116:AK120) | ... BD122: =SUM(BD116:BD120) | BE122: =I122-SUM(AB122:BD122)

Sheet 6、现金
A1: ←返回
A2: 行号 | B2: 交易时间 | C2: 销售费用 | D2: 管理费用 | E2: 财务费用 | F2: 应缴税金 | G2: 固定资产 | H2: 主营业务支出 | I2: 日常支出和 | J2: 集团往来 | K2: 理财 | L2: 提现 | M2: 押金/暂支款 | N2: 收入 | R2: 余额 | S2: 客户/供应商 | T2: 部门 | U2: 摘要 | V2: 主营业务支出 | AB2: 销售费用 | AK2: 管理费用 | AT2: 财务费用 | AV2: 应缴税金 | BA2: 有形资产
N3: 常年咨询服务 | O3: 涉税专项服务 | P3: 财税外包服务 | Q3: 企业培训服务 | V3: 服务费 | W3: 推广费 | X3: 佣金 | Y3: 劳务费 | Z3: 分成 | AA3: 其他 | AB3: 市场宣传 | AC3: 市场辅料 | AD3: 飞机、动车等 | AE3: 住宿费 | AF3: 车辆费 | AG3: 市内交通 | AH3: 招待/公关 | AI3: 服务费 | AJ3: 其他 | AK3: 办公用品&办公费 | AL3: 办公租金&物业费 | AM3: 交通费 | AN3: 招待费 | AO3: 服务费 | AP3: 人员薪资 | AQ3: 社保&公积金 | AR3: 员工福利 | AS3: 其他 | AT3: 手续费 | AU3: 利息 | AV3: 增值税及附加 | AW3: 所得税 | AX3: 印花税 | AY3: 工资个税 | AZ3: 劳务个税 | BA3: 办公设备 | BB3: 办公家具 (包含车等）
A4: XX期初余额 | I4: 0 | R4: 0
C5: =SUM(AB5:AJ5) | D5: =SUM(AK5:AS5) | E5: =SUM(AT5:AU5) | F5: =SUM(AV5:AZ5) | G5: =SUM(BA5:BD5) | H5: =SUM(V5:AA5) | I5: =SUM(C5:H5) | R5: =R4+SUM(N5:Q5)-SUM(I5:M5) | BE5: =I5-SUM(AB5:BD5)
C6: =SUM(AB6:AJ6) | D6: =SUM(AK6:AS6) | E6: =SUM(AT6:AU6) | F6: =SUM(AV6:AZ6) | G6: =SUM(BA6:BD6) | H6: =SUM(V6:AA6) | I6: =SUM(C6:H6) | R6: =R5+SUM(N6:Q6)-SUM(I6:M6) | BE6: =I6-SUM(AB6:BD6)
C7: =SUM(AB7:AJ7) | D7: =SUM(AK7:AS7) | E7: =SUM(AT7:AU7) | F7: =SUM(AV7:AZ7) | G7: =SUM(BA7:BD7) | H7: =SUM(V7:AA7) | I7: =SUM(C7:H7) | R7: =R6+SUM(N7:Q7)-SUM(I7:M7) | BE7: =I7-SUM(AB7:BD7)
C8: =SUM(AB8:AJ8) | D8: =SUM(AK8:AS8) | E8: =SUM(AT8:AU8) | F8: =SUM(AV8:AZ8) | G8: =SUM(BA8:BD8) | H8: =SUM(V8:AA8) | I8: =SUM(C8:H8) | R8: =R7+SUM(N8:Q8)-SUM(I8:M8) | BE8: =I8-SUM(AB8:BD8)
C9: =SUM(AB9:AJ9) | D9: =SUM(AK9:AS9) | E9: =SUM(AT9:AU9) | F9: =SUM(AV9:AZ9) | G9: =SUM(BA9:BD9) | H9: =SUM(V9:AA9) | I9: =SUM(C9:H9) | R9: =R8+SUM(N9:Q9)-SUM(I9:M9) | BE9: =I9-SUM(AB9:BD9)
C10: =SUM(AB10:AJ10) | D10: =SUM(AK10:AS10) | E10: =SUM(AT10:AU10) | F10: =SUM(AV10:AZ10) | G10: =SUM(BA10:BD10) | H10: =SUM(V10:AA10) | I10: =SUM(C10:H10) | R10: =R9+SUM(N10:Q10)-SUM(I10:M10) | BE10: =I10-SUM(AB10:BD10)
C11: =SUM(AB11:AJ11) | D11: =SUM(AK11:AS11) | E11: =SUM(AT11:AU11) | F11: =SUM(AV11:AZ11) | G11: =SUM(BA11:BD11) | H11: =SUM(V11:AA11) | I11: =SUM(C11:H11) | R11: =R10+SUM(N11:Q11)-SUM(I11:M11) | BE11: =I11-SUM(AB11:BD11)
C12: =SUM(AB12:AJ12) | D12: =SUM(AK12:AS12) | E12: =SUM(AT12:AU12) | F12: =SUM(AV12:AZ12) | G12: =SUM(BA12:BD12) | H12: =SUM(V12:AA12) | I12: =SUM(C12:H12) | R12: =R11+SUM(N12:Q12)-SUM(I12:M12) | BE12: =I12-SUM(AB12:BD12)
C13: =SUM(AB13:AJ13) | D13: =SUM(AK13:AS13) | E13: =SUM(AT13:AU13) | F13: =SUM(AV13:AZ13) | G13: =SUM(BA13:BD13) | H13: =SUM(V13:AA13) | I13: =SUM(C13:H13) | R13: =R12+SUM(N13:Q13)-SUM(I13:M13) | BE13: =I13-SUM(AB13:BD13)
C14: =SUM(AB14:AJ14) | D14: =SUM(AK14:AS14) | E14: =SUM(AT14:AU14) | F14: =SUM(AV14:AZ14) | G14: =SUM(BA14:BD14) | H14: =SUM(V14:AA14) | I14: =SUM(C14:H14) | R14: =R13+SUM(N14:Q14)-SUM(I14:M14) | BE14: =I14-SUM(AB14:BD14)
C15: =SUM(AB15:AJ15) | D15: =SUM(AK15:AS15) | E15: =SUM(AT15:AU15) | F15: =SUM(AV15:AZ15) | G15: =SUM(BA15:BD15) | H15: =SUM(V15:AA15) | I15: =SUM(C15:H15) | R15: =R14+SUM(N15:Q15)-SUM(I15:M15) | BE15: =I15-SUM(AB15:BD15)
C16: =SUM(AB16:AJ16) | D16: =SUM(AK16:AS16) | E16: =SUM(AT16:AU16) | F16: =SUM(AV16:AZ16) | G16: =SUM(BA16:BD16) | H16: =SUM(V16:AA16) | I16: =SUM(C16:H16) | R16: =R15+SUM(N16:Q16)-SUM(I16:M16) | BE16: =I16-SUM(AB16:BD16)
... C45: =SUM(AB45:AJ45) | D45: =SUM(AK45:AS45) | E45: =SUM(AT45:AU45) | F45: =SUM(AV45:AZ45) | G45: =SUM(BA45:BD45) | H45: =SUM(V45:AA45) | I45: =SUM(C45:H45) | R45: =R44+SUM(N45:Q45)-SUM(I45:M45) | BE45: =I45-SUM(AB45:BD45)
C46: =SUM(AB46:AJ46) | D46: =SUM(AK46:AS46) | E46: =SUM(AT46:AU46) | F46: =SUM(AV46:AZ46) | G46: =SUM(BA46:BD46) | H46: =SUM(V46:AA46) | I46: =SUM(C46:H46) | R46: =R45+SUM(N46:Q46)-SUM(I46:M46)
C47: =SUM(AB47:AJ47) | D47: =SUM(AK47:AS47) | E47: =SUM(AT47:AU47) | F47: =SUM(AV47:AZ47) | G47: =SUM(BA47:BD47) | H47: =SUM(V47:AA47) | I47: =SUM(C47:H47) | R47: =R46+SUM(N47:Q47)-SUM(I47:M47) | BE47: =I47-SUM(AB47:BD47)
C48: =SUM(AB48:AJ48) | D48: =SUM(AK48:AS48) | E48: =SUM(AT48:AU48) | F48: =SUM(AV48:AZ48) | G48: =SUM(BA48:BD48) | H48: =SUM(V48:AA48) | I48: =SUM(C48:H48) | R48: =R47+SUM(N48:Q48)-SUM(I48:M48) | BE48: =I48-SUM(AB48:BD48)
C49: =SUM(AB49:AJ49) | D49: =SUM(AK49:AS49) | E49: =SUM(AT49:AU49) | F49: =SUM(AV49:AZ49) | G49: =SUM(BA49:BD49) | H49: =SUM(V49:AA49) | I49: =SUM(C49:H49) | R49: =R48+SUM(N49:Q49)-SUM(I49:M49) | BE49: =I49-SUM(AB49:BD49)
C50: =SUM(AB50:AJ50) | D50: =SUM(AK50:AS50) | E50: =SUM(AT50:AU50) | F50: =SUM(AV50:AZ50) | G50: =SUM(BA50:BD50) | H50: =SUM(V50:AA50) | I50: =SUM(C50:H50) | R50: =R49+SUM(N50:Q50)-SUM(I50:M50) | BE50: =I50-SUM(AB50:BD50)
C51: =SUM(AB51:AJ51) | D51: =SUM(AK51:AS51) | E51: =SUM(AT51:AU51) | F51: =SUM(AV51:AZ51) | G51: =SUM(BA51:BD51) | H51: =SUM(V51:AA51) | I51: =SUM(C51:H51) | R51: =R50+SUM(N51:Q51)-SUM(I51:M51) | BE51: =I51-SUM(AB51:BD51)
C52: =SUM(AB52:AJ52) | D52: =SUM(AK52:AS52) | E52: =SUM(AT52:AU52) | F52: =SUM(AV52:AZ52) | G52: =SUM(BA52:BD52) | H52: =SUM(V52:AA52) | I52: =SUM(C52:H52) | R52: =R51+SUM(N52:Q52)-SUM(I52:M52) | BE52: =I52-SUM(AB52:BD52)
C53: =SUM(AB53:AJ53) | D53: =SUM(AK53:AS53) | E53: =SUM(AT53:AU53) | F53: =SUM(AV53:AZ53) | G53: =SUM(BA53:BD53) | H53: =SUM(V53:AA53) | I53: =SUM(C53:H53) | R53: =R52+SUM(N53:Q53)-SUM(I53:M53) | BE53: =I53-SUM(AB53:BD53)
C54: =SUM(AB54:AJ54) | D54: =SUM(AK54:AS54) | E54: =SUM(AT54:AU54) | F54: =SUM(AV54:AZ54) | G54: =SUM(BA54:BD54) | H54: =SUM(V54:AA54) | I54: =SUM(C54:H54) | R54: =R53+SUM(N54:Q54)-SUM(I54:M54) | BE54: =I54-SUM(AB54:BD54)
C55: =SUM(AB55:AJ55) | D55: =SUM(AK55:AS55) | E55: =SUM(AT55:AU55) | F55: =SUM(AV55:AZ55) | G55: =SUM(BA55:BD55) | H55: =SUM(V55:AA55) | I55: =SUM(C55:H55) | R55: =R54+SUM(N55:Q55)-SUM(I55:M55) | BE55: =I55-SUM(AB55:BD55)
C56: =SUM(AB56:AJ56) | D56: =SUM(AK56:AS56) | E56: =SUM(AT56:AU56) | F56: =SUM(AV56:AZ56) | G56: =SUM(BA56:BD56) | H56: =SUM(V56:AA56) | I56: =SUM(C56:H56) | R56: =R55+SUM(N56:Q56)-SUM(I56:M56) | BE56: =I56-SUM(AB56:BD56)
C57: =SUM(AB57:AJ57) | D57: =SUM(AK57:AS57) | E57: =SUM(AT57:AU57) | F57: =SUM(AV57:AZ57) | G57: =SUM(BA57:BD57) | H57: =SUM(V57:AA57) | I57: =SUM(C57:H57) | R57: =R56+SUM(N57:Q57)-SUM(I57:M57) | BE57: =I57-SUM(AB57:BD57)
C58: =SUM(AB58:AJ58) | D58: =SUM(AK58:AS58) | E58: =SUM(AT58:AU58) | F58: =SUM(AV58:AZ58) | G58: =SUM(BA58:BD58) | H58: =SUM(V58:AA58) | I58: =SUM(C58:H58) | R58: =R57+SUM(N58:Q58)-SUM(I58:M58) | BE58: =I58-SUM(AB58:BD58)
... C113: =SUM(AB113:AJ113) | D113: =SUM(AK113:AS113) | E113: =SUM(AT113:AU113) | F113: =SUM(AV113:AZ113) | G113: =SUM(BA113:BD113) | H113: =SUM(V113:AA113) | I113: =SUM(C113:H113) | R113: =R112+SUM(N113:Q113)-SUM(I113:M113) | BE113: =I113-SUM(AB113:BD113)
A114: 合计 | C114: =SUM(C5:C113) | D114: =SUM(D5:D113) | E114: =SUM(E5:E113) | F114: =SUM(F5:F113) | G114: =SUM(G5:G113) | H114: =SUM(H5:H113) | I114: =SUM(I5:I113) | J114: =SUM(J5:J113) | ... N114: =SUM(N5:N113) | P114: =SUM(P5:P113) | Q114: =SUM(Q5:Q113) | R114: =R4+N114+P114+Q114-M114-L114-K114-J114-I114 | V114: =SUM(V5:V113) | W114: =SUM(W5:W113) | X114: =SUM(X5:X113) | Y114: =SUM(Y5:Y113) | Z114: =SUM(Z5:Z113) | AA114: =SUM(AA5:AA113) | AB114: =SUM(AB5:AB113) | AC114: =SUM(AC5:AC113) | ... BD114: =SUM(BD5:BD113) | BE114: =I114-SUM(AB114:BD114)
A115: SPD-5465-理财产品期初余额 | I115: =SUM(C115:H115) | R115: =R114+SUM(N115:Q115)-SUM(I115:M115)
C116: =SUM(AB116:AJ116) | D116: =SUM(AK116:AS116) | E116: =SUM(AT116:AU116) | F116: =SUM(AV116:AZ116) | G116: =SUM(BA116:BD116) | H116: =SUM(V116:AA116) | I116: =SUM(C116:H116) | R116: =R115+SUM(N116:Q116)-SUM(I116:M116) | BE116: =I116-SUM(AB116:BD116)
C117: =SUM(AB117:AJ117) | D117: =SUM(AK117:AS117) | E117: =SUM(AT117:AU117) | F117: =SUM(AV117:AZ117) | G117: =SUM(BA117:BD117) | H117: =SUM(V117:AA117) | I117: =SUM(C117:H117) | R117: =R116+SUM(N117:Q117)-SUM(I117:M117) | BE117: =I117-SUM(AB117:BD117)
C118: =SUM(AB118:AJ118) | D118: =SUM(AK118:AS118) | E118: =SUM(AT118:AU118) | F118: =SUM(AV118:AZ118) | G118: =SUM(BA118:BD118) | H118: =SUM(V118:AA118) | I118: =SUM(C118:H118) | R118: =R117+SUM(N118:Q118)-SUM(I118:M118) | BE118: =I118-SUM(AB118:BD118)
